Workbook

Sheet CONTROL CALIBRACIONES
C1: CONTROL CALIBRACIÓN EQUIPOS E INSTRUMENTOS
C3: CODIGO | D3: OYS-FO-42 | F3: VERSION | G3: 05 | I3: FECHA | L3: 45950
C6: Fecha de actualización | E6: 45924
C9: CONTROL CALIBRACIÓN EQUIPOS E INSTRUMENTOS
A12: PLANTA
A13: IDENTIFICACIÓN | B13: EQUIPO / INSTRUMENTO | C13: FABRICANTE | D13: CERTIFICADO No. | E13: MODELO | F13: SERIE | G13: FECHA DE CALIBRACION | H13: FECHA PROXIMA CALIBRACIÓN | I13: ESTADO CALIBRACIÓN | J13: ESTADO FíSICO | K13: CERTIFICADOR | L13: RANGO | M13: ESTADO
A14: MAN-001 | B14: MANÓMETRO DIGITAL | C14: CRYSTAL | D14: MIS-LP-2025-01-0214 | E14: XP2i | F14: 357309 | G14: 45681 | H14: =+G14+365 -> 46046 | I14: =IF(H14<TODAY(),"VENCIDO",IF(H14-TODAY()<15,"PROXIMO A VENCER","CERTIFICADO")) -> CERTIFICADO | J14: BUENO | K14: METROLOGY | L14: 0-3000 psi | M14: =IF(AND(J14="MALO",OR(I14="CERTIFICADO",I14="PROXIMO A VENCER",I14="VENCIDO")),"🔴", IF(AND(J14="BUENO",OR(I14="CERTIFICADO",I14="PROXIMO A VENCER")),"🟢", IF(AND(J14="BUENO",I14="VENCIDO"),"🟡",""))) -> 🟢
A15: MAN-002 | B15: MANÓMETRO DIGITAL | C15: ADDITEL | D15: MIS-LP-2024-12-1761 | E15: 681 | F15: 211H200A0024 | G15: 45635 | H15: =+G15+365 -> 46000 | I15: =IF(H15<TODAY(),"VENCIDO",IF(H15-TODAY()<15,"PROXIMO A VENCER","CERTIFICADO")) -> CERTIFICADO | J15: BUENO | K15: METROLOGY | L15: 0-3000 psi | M15: =IF(AND(J15="MALO",OR(I15="CERTIFICADO",I15="PROXIMO A VENCER",I15="VENCIDO")),"🔴", IF(AND(J15="BUENO",OR(I15="CERTIFICADO",I15="PROXIMO A VENCER")),"🟢", IF(AND(J15="BUENO",I15="VENCIDO"),"🟡",""))) -> 🟢
A16: MAN-003 | B16: MANÓMETRO DIGITAL | C16: AMETEK CRYSTAL | D16: MIS-LP-2024-12-1618 | E16: XP2i | F16: 104696 | G16: 45628 | H16: =+G16+365 -> 45993 | I16: =IF(H16<TODAY(),"VENCIDO",IF(H16-TODAY()<15,"PROXIMO A VENCER","CERTIFICADO")) -> CERTIFICADO | J16: BUENO | K16: METROLOGY | L16: 0-5000 psi | M16: =IF(AND(J16="MALO",OR(I16="CERTIFICADO",I16="PROXIMO A VENCER",I16="VENCIDO")),"🔴", IF(AND(J16="BUENO",OR(I16="CERTIFICADO",I16="PROXIMO A VENCER")),"🟢", IF(AND(J16="BUENO",I16="VENCIDO"),"🟡",""))) -> 🟢
A17: MAN-004 | B17: MANÓMETRO Y TRANSMISOR DE BAJA PRESIÓN | C17: SIEMENS | D17: MIS-LP-2024-1440 | E17: D-76181 | F17: N1-T503-9508911 | G17: 45594 | H17: =+G17+365 -> 45959 | I17: =IF(H17<TODAY(),"VENCIDO",IF(H17-TODAY()<15,"PROXIMO A VENCER","CERTIFICADO")) -> VENCIDO | J17: BUENO | K17: METROLOGY | L17: 0-3,61 psi | M17: =IF(AND(J17="MALO",OR(I17="CERTIFICADO",I17="PROXIMO A VENCER",I17="VENCIDO")),"🔴", IF(AND(J17="BUENO",OR(I17="CERTIFICADO",I17="PROXIMO A VENCER")),"🟢", IF(AND(J17="BUENO",I17="VENCIDO"),"🟡",""))) -> 🟡
A18: MAN-005 | B18: MANÓMETRO DIGITAL | C18: AMETEK CRYSTAL | D18: 12652 | E18: XP2i | F18: 322944 | G18: 45775 | H18: =+G18+365 -> 46140 | I18: =IF(H18<TODAY(),"VENCIDO",IF(H18-TODAY()<15,"PROXIMO A VENCER","CERTIFICADO")) -> CERTIFICADO | J18: BUENO | K18: FLEXILATINA | L18: 0-1000 psi | M18: =IF(AND(J18="MALO",OR(I18="CERTIFICADO",I18="PROXIMO A VENCER",I18="VENCIDO")),"🔴", IF(AND(J18="BUENO",OR(I18="CERTIFICADO",I18="PROXIMO A VENCER")),"🟢", IF(AND(J18="BUENO",I18="VENCIDO"),"🟡",""))) -> 🟢
A19: MAN-006 | B19: MANÓMETRO DIGITAL | C19: WIKA | D19: N/A | E19: N/A | F19: N/A | G19: 0 | H19: 0 | I19: =IF(H19<TODAY(),"VENCIDO",IF(H19-TODAY()<15,"PROXIMO A VENCER","CERTIFICADO")) -> VENCIDO | J19: BUENO | K19: N/A | L19: N/A | M19: =IF(AND(J19="MALO",OR(I19="CERTIFICADO",I19="PROXIMO A VENCER",I19="VENCIDO")),"🔴", IF(AND(J19="BUENO",OR(I19="CERTIFICADO",I19="PROXIMO A VENCER")),"🟢", IF(AND(J19="BUENO",I19="VENCIDO"),"🟡",""))) -> 🟡
A20: FLX-001 | B20: FLEXÓMETRO | C20: TRUPER | D20: CD-10090 | E20: FH-5M | F20: UK 0126 0022 | G20: 45796 | H20: =+G20+365 -> 46161 | I20: =IF(H20<TODAY(),"VENCIDO",IF(H20-TODAY()<15,"PROXIMO A VENCER","CERTIFICADO")) -> CERTIFICADO | J20: BUENO | K20: METROTEST | L20: 5m | M20: =IF(AND(J20="MALO",OR(I20="CERTIFICADO",I20="PROXIMO A VENCER",I20="VENCIDO")),"🔴", IF(AND(J20="BUENO",OR(I20="CERTIFICADO",I20="PROXIMO A VENCER")),"🟢", IF(AND(J20="BUENO",I20="VENCIDO"),"🟡",""))) -> 🟢
A21: PDR-001 | B21: PIE DE REY DIGITAL | C21: INSIZE | D21: CD-10088 | E21: 1108-200 | F21: 1212181369 | G21: 45796 | H21: =+G21+365 -> 46161 | I21: =IF(H21<TODAY(),"VENCIDO",IF(H21-TODAY()<15,"PROXIMO A VENCER","CERTIFICADO")) -> CERTIFICADO | J21: BUENO | K21: METROTEST | L21: 0-200 mm | M21: =IF(AND(J21="MALO",OR(I21="CERTIFICADO",I21="PROXIMO A VENCER",I21="VENCIDO")),"🔴", IF(AND(J21="BUENO",OR(I21="CERTIFICADO",I21="PROXIMO A VENCER")),"🟢", IF(AND(J21="BUENO",I21="VENCIDO"),"🟡",""))) -> 🟢
A22: PDR-002 | B22: PIE DE REY DIGITAL | C22: MITUTOYO | D22: CD-10089 | E22: CD-6" CSX-B | F22: BH010822 | G22: 45796 | H22: =+G22+365 -> 46161 | I22: =IF(H22<TODAY(),"VENCIDO",IF(H22-TODAY()<15,"PROXIMO A VENCER","CERTIFICADO")) -> CERTIFICADO | J22: BUENO | K22: METROTEST | L22: 0-150 mm | M22: =IF(AND(J22="MALO",OR(I22="CERTIFICADO",I22="PROXIMO A VENCER",I22="VENCIDO")),"🔴", IF(AND(J22="BUENO",OR(I22="CERTIFICADO",I22="PROXIMO A VENCER")),"🟢", IF(AND(J22="BUENO",I22="VENCIDO"),"🟡",""))) -> 🟢
A23: THB-001 | B23: TERMOHIGROBAROMETRO | C23: TESTO | D23: HR-4914-25 // TE-8606-25 | E23: 622 | F23: 39536692/0323 | G23: 45695 | H23: =+G23+365 -> 46060 | I23: =IF(H23<TODAY(),"VENCIDO",IF(H23-TODAY()<15,"PROXIMO A VENCER","CERTIFICADO")) -> CERTIFICADO | J23: BUENO | K23: VALMET L&M | L23: 0-100% // -20°C a 60°C | M23: =IF(AND(J23="MALO",OR(I23="CERTIFICADO",I23="PROXIMO A VENCER",I23="VENCIDO")),"🔴", IF(AND(J23="BUENO",OR(I23="CERTIFICADO",I23="PROXIMO A VENCER")),"🟢", IF(AND(J23="BUENO",I23="VENCIDO"),"🟡",""))) -> 🟢
D24: MET-LP-CC 12662 | G24: 45793 | H24: =+G24+365 -> 46158 | I24: =IF(H24<TODAY(),"VENCIDO",IF(H24-TODAY()<15,"PROXIMO A VENCER","CERTIFICADO")) -> CERTIFICADO | J24: BUENO | K24: METROLABOR | L24: 300 hPa a 1200 hPa | M24: =IF(AND(J24="MALO",OR(I24="CERTIFICADO",I24="PROXIMO A VENCER",I24="VENCIDO")),"🔴", IF(AND(J24="BUENO",OR(I24="CERTIFICADO",I24="PROXIMO A VENCER")),"🟢", IF(AND(J24="BUENO",I24="VENCIDO"),"🟡",""))) -> 🟢
A25: THB-002 | B25: TERMOHIGROMETRO | C25: KEX GERMANY | D25: HR-28703 // TA-28702 | E25: SH-172 | F25: 50898 | G25: 45798 | H25: =+G25+365 -> 46163 | I25: =IF(H25<TODAY(),"VENCIDO",IF(H25-TODAY()<15,"PROXIMO A VENCER","CERTIFICADO")) -> CERTIFICADO | J25: BUENO | K25: FYH | L25: 10-90% // -50°C a 70°C | M25: =IF(AND(J25="MALO",OR(I25="CERTIFICADO",I25="PROXIMO A VENCER",I25="VENCIDO")),"🔴", IF(AND(J25="BUENO",OR(I25="CERTIFICADO",I25="PROXIMO A VENCER")),"🟢", IF(AND(J25="BUENO",I25="VENCIDO"),"🟡",""))) -> 🟢
A27: VST2
A28: IDENTIFICACIÓN | B28: EQUIPO / INSTRUMENTO | C28: FABRICANTE | D28: CERTIFICADO No. | E28: MODELO | F28: SERIE | G28: FECHA DE CALIBRACION | H28: FECHA PROXIMA CALIBRACIÓN | I28: CALIBRACIÓN | J28: ESTADO FíSICO | K28: CERTIFICADOR | L28: RANGO | M28: ESTADO
A29: CEC-005 | B29: DINAMOMETRO | C29: TRUMAX | D29: 8472 | E29: SC-2,5Klb // VST3000 | F29: 2301129900 // V00220 | G29: 45786 | H29: =+G29+365 -> 46151 | I29: =IF(H29<TODAY(),"VENCIDO",IF(H29-TODAY()<15,"PROXIMO A VENCER","CERTIFICADO")) -> CERTIFICADO | J29: BUENO | K29: SERVINTEGRAL | L29: 2500 lb-f | M29: =IF(AND(J29="MALO",OR(I29="CERTIFICADO",I29="PROXIMO A VENCER",I29="VENCIDO")),"🔴", IF(AND(J29="BUENO",OR(I29="CERTIFICADO",I29="PROXIMO A VENCER")),"🟢", IF(AND(J29="BUENO",I29="VENCIDO"),"🟡",""))) -> 🟢
A30: CEC-006 | B30: DINAMOMETRO | C30: VALSER / TEK | D30: 8531 | E30: 516 2 t // VST3000 | F30: 17080195 // V00220 | G30: 45824 | H30: =+G30+365 -> 46189 | I30: =IF(H30<TODAY(),"VENCIDO",IF(H30-TODAY()<15,"PROXIMO A VENCER","CERTIFICADO")) -> CERTIFICADO | J30: BUENO | K30: SERVINTEGRAL | L30: 4400 lb-f | M30: =IF(AND(J30="MALO",OR(I30="CERTIFICADO",I30="PROXIMO A VENCER",I30="VENCIDO")),"🔴", IF(AND(J30="BUENO",OR(I30="CERTIFICADO",I30="PROXIMO A VENCER")),"🟢", IF(AND(J30="BUENO",I30="VENCIDO"),"🟡",""))) -> 🟢
A31: CEC-007 | B31: DINAMOMETRO | C31: TRUMAX | D31: 8217 | E31: SG-5T | F31: 2309210270 | G31: 45611 | H31: =+G31+365 -> 45976 | I31: =IF(H31<TODAY(),"VENCIDO",IF(H31-TODAY()<15,"PROXIMO A VENCER","CERTIFICADO")) -> PROXIMO A VENCER | J31: BUENO | K31: SERVINTEGRAL | L31: 9920 lb-f | M31: =IF(AND(J31="MALO",OR(I31="CERTIFICADO",I31="PROXIMO A VENCER",I31="VENCIDO")),"🔴", IF(AND(J31="BUENO",OR(I31="CERTIFICADO",I31="PROXIMO A VENCER")),"🟢", IF(AND(J31="BUENO",I31="VENCIDO"),"🟡",""))) -> 🟢
A32: TP-008 | B32: TRANSMISOR DE PRESION CON INDICACION DIGITAL | C32: DANFOSS | D32: 13029 | E32: MBS3000 | F32: 051950519282 | G32: 45901 | H32: =+G32+365 -> 46266 | I32: =IF(H32<TODAY(),"VENCIDO",IF(H32-TODAY()<15,"PROXIMO A VENCER","CERTIFICADO")) -> CERTIFICADO | J32: BUENO | K32: FLEXILATINA | L32: 0-870 psi | M32: =IF(AND(J32="MALO",OR(I32="CERTIFICADO",I32="PROXIMO A VENCER",I32="VENCIDO")),"🔴", IF(AND(J32="BUENO",OR(I32="CERTIFICADO",I32="PROXIMO A VENCER")),"🟢", IF(AND(J32="BUENO",I32="VENCIDO"),"🟡",""))) -> 🟢
A33: TP-009 | B33: TRANSMISOR DE PRESION CON INDICACION DIGITAL | C33: DANFOSS | D33: 13030 | E33: MBS3000 | F33: 20275210 | G33: 45897 | H33: =+G33+365 -> 46262 | I33: =IF(H33<TODAY(),"VENCIDO",IF(H33-TODAY()<15,"PROXIMO A VENCER","CERTIFICADO")) -> CERTIFICADO | J33: BUENO | K33: FLEXILATINA | L33: 0-3625 psi | M33: =IF(AND(J33="MALO",OR(I33="CERTIFICADO",I33="PROXIMO A VENCER",I33="VENCIDO")),"🔴", IF(AND(J33="BUENO",OR(I33="CERTIFICADO",I33="PROXIMO A VENCER")),"🟢", IF(AND(J33="BUENO",I33="VENCIDO"),"🟡",""))) -> 🟢
A35: VST3
A36: IDENTIFICACIÓN | B36: EQUIPO / INSTRUMENTO | C36: FABRICANTE | D36: CERTIFICADO No. | E36: MODELO | F36: SERIE | G36: FECHA DE CALIBRACION | H36: FECHA PROXIMA CALIBRACIÓN | I36: CALIBRACIÓN | J36: ESTADO FíSICO | K36: CERTIFICADOR | L36: RANGO | M36: ESTADO
A37: CEC-001 | B37: DINAMOMETRO | C37: TRUMAX | D37: 8642 | E37: SA-1Klb | F37: J181015117 | G37: 45860 | H37: =+G37+365 -> 46225 | I37: =IF(H37<TODAY(),"VENCIDO",IF(H37-TODAY()<15,"PROXIMO A VENCER","CERTIFICADO")) -> CERTIFICADO | J37: BUENO | K37: SERVINTEGRAL | L37: 950 lb-f | M37: =IF(AND(J37="MALO",OR(I37="CERTIFICADO",I37="PROXIMO A VENCER",I37="VENCIDO")),"🔴", IF(AND(J37="BUENO",OR(I37="CERTIFICADO",I37="PROXIMO A VENCER")),"🟢", IF(AND(J37="BUENO",I37="VENCIDO"),"🟡",""))) -> 🟢
A38: CEC-002 | B38: DINAMOMETRO | C38: GALOCE | D38: 7838 | E38: G55406 | F38: 20110066/VST1 | G38: 45363 | H38: =+G38+365 -> 45728 | I38: =IF(H38<TODAY(),"VENCIDO",IF(H38-TODAY()<15,"PROXIMO A VENCER","CERTIFICADO")) -> VENCIDO | J38: BUENO | K38: SERVINTEGRAL | L38: 2500 lb-f | M38: =IF(AND(J38="MALO",OR(I38="CERTIFICADO",I38="PROXIMO A VENCER",I38="VENCIDO")),"🔴", IF(AND(J38="BUENO",OR(I38="CERTIFICADO",I38="PROXIMO A VENCER")),"🟢", IF(AND(J38="BUENO",I38="VENCIDO"),"🟡",""))) -> 🟡
A39: CEC-004 | B39: DINAMOMETRO | C39: BBG | D39: 8532 | E39: TSC // VST3000 | F39: 810551 | G39: 45824 | H39: =+G39+365 -> 46189 | I39: =IF(H39<TODAY(),"VENCIDO",IF(H39-TODAY()<15,"PROXIMO A VENCER","CERTIFICADO")) -> CERTIFICADO | J39: BUENO | K39: SERVINTEGRAL | L39: 2200 lb-f | M39: =IF(AND(J39="MALO",OR(I39="CERTIFICADO",I39="PROXIMO A VENCER",I39="VENCIDO")),"🔴", IF(AND(J39="BUENO",OR(I39="CERTIFICADO",I39="PROXIMO A VENCER")),"🟢", IF(AND(J39="BUENO",I39="VENCIDO"),"🟡",""))) -> 🟢
A40: CEC-003 | B40: DINAMOMETRO | C40: TRUMAX | D40: 8533 | E40: SC-5Klb // VST3000 | F40: M190927007 | G40: 45824 | H40: =+G40+365 -> 46189 | I40: =IF(H40<TODAY(),"VENCIDO",IF(H40-TODAY()<15,"PROXIMO A VENCER","CERTIFICADO")) -> CERTIFICADO | J40: BUENO | K40: SERVINTEGRAL | L40: 5000 lb-f | M40: =IF(AND(J40="MALO",OR(I40="CERTIFICADO",I40="PROXIMO A VENCER",I40="VENCIDO")),"🔴", IF(AND(J40="BUENO",OR(I40="CERTIFICADO",I40="PROXIMO A VENCER")),"🟢", IF(AND(J40="BUENO",I40="VENCIDO"),"🟡",""))) -> 🟢
A41: TP-004 | B41: TRANSMISOR DE PRESION CON INDICACION DIGITAL | C41: DANFOSS | D41: 13098 | E41: MBS3000 | F41: 92833390 | G41: 45919 | H41: =+G41+365 -> 46284 | I41: =IF(H41<TODAY(),"VENCIDO",IF(H41-TODAY()<15,"PROXIMO A VENCER","CERTIFICADO")) -> CERTIFICADO | J41: BUENO | K41: FLEXILATINA | L41: 0-145 psi | M41: =IF(AND(J41="MALO",OR(I41="CERTIFICADO",I41="PROXIMO A VENCER",I41="VENCIDO")),"🔴", IF(AND(J41="BUENO",OR(I41="CERTIFICADO",I41="PROXIMO A VENCER")),"🟢", IF(AND(J41="BUENO",I41="VENCIDO"),"🟡",""))) -> 🟢
A42: TP-001 | B42: TRANSMISOR DE PRESION CON INDICACION DIGITAL | C42: RITHERM | D42: 13032 | E42: 3000 | F42: 2074022 | G42: 45901 | H42: =+G42+365 -> 46266 | I42: =IF(H42<TODAY(),"VENCIDO",IF(H42-TODAY()<15,"PROXIMO A VENCER","CERTIFICADO")) -> CERTIFICADO | J42: MALO | K42: FLEXILATINA | L42: 0-1000 psi | M42: =IF(AND(J42="MALO",OR(I42="CERTIFICADO",I42="PROXIMO A VENCER",I42="VENCIDO")),"🔴", IF(AND(J42="BUENO",OR(I42="CERTIFICADO",I42="PROXIMO A VENCER")),"🟢", IF(AND(J42="BUENO",I42="VENCIDO"),"🟡",""))) -> 🔴
A43: TP-002 | B43: TRANSMISOR DE PRESION CON INDICACION DIGITAL | C43: APLISENS | D43: 13031 | E43: PCE-28 | F43: 11121025 | G43: 45897 | H43: =+G43+365 -> 46262 | I43: =IF(H43<TODAY(),"VENCIDO",IF(H43-TODAY()<15,"PROXIMO A VENCER","CERTIFICADO")) -> CERTIFICADO | J43: BUENO | K43: FLEXILATINA | L43: 0-5000 psi | M43: =IF(AND(J43="MALO",OR(I43="CERTIFICADO",I43="PROXIMO A VENCER",I43="VENCIDO")),"🔴", IF(AND(J43="BUENO",OR(I43="CERTIFICADO",I43="PROXIMO A VENCER")),"🟢", IF(AND(J43="BUENO",I43="VENCIDO"),"🟡",""))) -> 🟢
A44: TP-003 | B44: TRANSMISOR DE PRESION CON INDICACION DIGITAL | C44: SINTEK | D44: PLAB-23-480 | E44: - | F44: NPIR-23-155 | G44: 45062 | H44: =+G44+365 -> 45427 | I44: =IF(H44<TODAY(),"VENCIDO",IF(H44-TODAY()<15,"PROXIMO A VENCER","CERTIFICADO")) -> VENCIDO | J44: BUENO | K44: METROLOGY | L44: 0-15000 psi | M44: =IF(AND(J44="MALO",OR(I44="CERTIFICADO",I44="PROXIMO A VENCER",I44="VENCIDO")),"🔴", IF(AND(J44="BUENO",OR(I44="CERTIFICADO",I44="PROXIMO A VENCER")),"🟢", IF(AND(J44="BUENO",I44="VENCIDO"),"🟡",""))) -> 🟡

Sheet datos
A1: BUENO
A2: MALO

Sheet VERIFICACIÓN MAN-001
B2: INTRUMENTO | C2: MARCA | D2: MODELO | E2: SERIAL | F2: FECHA DE CALIBRACIÓN
B3: PATRÓN | C3: CRYSTAL | D3: =IF($C$3='CONTROL CALIBRACIONES'!$C$14,'CONTROL CALIBRACIONES'!E14,IF($C$3='CONTROL CALIBRACIONES'!$C$15,'CONTROL CALIBRACIONES'!E15,'CONTROL CALIBRACIONES'!E16)) -> XP2i | E3: =IF($C$3='CONTROL CALIBRACIONES'!$C$14,'CONTROL CALIBRACIONES'!F14,IF($C$3='CONTROL CALIBRACIONES'!$C$15,'CONTROL CALIBRACIONES'!F15,'CONTROL CALIBRACIONES'!F16)) -> 357309 | F3: ='CONTROL CALIBRACIONES'!G14 -> 45681
B5: DATOS Y RESULTADOS DE LA CALIBRACIÓN
B7: VALOR PATRÓN (psi) | C7: VALOR IBV (psi) | D7: ERROR (psi) | E7: INCERTIDUMBRE | F7: Error permitido (+- psi) | G7: COMENTARIOS | K7: Superior | L7: Inferior
A8: 1 | B8: 300 | C8: 299.5 | D8: =C8-B8 -> -0.5 | E8: 0.4 | F8: =IF(AND(B8>15,B8<=70),1,IF(AND(B8>70,B8<=300),B8*0.015,IF(AND(B8>300,B8<=1000),6,IF(AND(B8>1000),B8*0.005,"Revisar")))) -> 4.5 | H8: PRESIÓN ATMOSFERICA (hPa) | I8: 751.1 | K8: =F8 -> 4.5 | L8: =-F8 -> -4.5
A9: 2 | B9: 600 | C9: 601.4 | D9: =C9-B9 -> 1.4 | E9: 0.39 | F9: =IF(AND(B9>15,B9<=70),1,IF(AND(B9>70,B9<=300),B9*0.015,IF(AND(B9>300,B9<=1000),6,IF(AND(B9>1000),B9*0.005,"Revisar")))) -> 6 | H9: HUMEDAD RELATIVA (%) | I9: 49.4 | K9: =F9 -> 6 | L9: =-F9 -> -6
A10: 3 | B10: 900 | C10: 901.6 | D10: =C10-B10 -> 1.6 | E10: 0.45 | F10: =IF(AND(B10>15,B10<=70),1,IF(AND(B10>70,B10<=300),B10*0.015,IF(AND(B10>300,B10<=1000),6,IF(AND(B10>1000),B10*0.005,"Revisar")))) -> 6 | H10: ENTE CERTIFICADOR | I10: Metrology | K10: =F10 -> 6 | L10: =-F10 -> -6
A11: 4 | B11: 1200 | C11: 1200.1 | D11: =C11-B11 -> 0.1 | E11: 0.86 | F11: =IF(AND(B11>15,B11<=70),1,IF(AND(B11>70,B11<=300),B11*0.015,IF(AND(B11>300,B11<=1000),6,IF(AND(B11>1000),B11*0.005,"Revisar")))) -> 6 | H11: FECHA DE CALIBRACIÓN | I11: 45635 | K11: =F11 -> 6 | L11: =-F11 -> -6
A12: 5 | B12: 1500 | C12: 1501.3 | D12: =C12-B12 -> 1.3 | E12: 0.48 | F12: =IF(AND(B12>15,B12<=70),1,IF(AND(B12>70,B12<=300),B12*0.015,IF(AND(B12>300,B12<=1000),6,IF(AND(B12>1000),B12*0.005,"Revisar")))) -> 7.5 | H12: Después de que el equipo llega, se confirma que calibrando con un tiempo calendario de 1 año, el equipo sigue cumpliendo con las especificaiones requeridas, por lo cual se mantiene el periodo de un año según lo establecido en la OIML 10 método 1 | K12: =F12 -> 7.5 | L12: =-F12 -> -7.5
A13: 6 | B13: 1800 | C13: 1800.4 | D13: =C13-B13 -> 0.4 | E13: 0.8 | F13: =IF(AND(B13>15,B13<=70),1,IF(AND(B13>70,B13<=300),B13*0.015,IF(AND(B13>300,B13<=1000),6,IF(AND(B13>1000),B13*0.005,"Revisar")))) -> 9 | K13: =F13 -> 9 | L13: =-F13 -> -9
A14: 7 | B14: 2100 | C14: 2099.1 | D14: =C14-B14 -> -0.9 | E14: 0.5 | F14: =IF(AND(B14>15,B14<=70),1,IF(AND(B14>70,B14<=300),B14*0.015,IF(AND(B14>300,B14<=1000),6,IF(AND(B14>1000),B14*0.005,"Revisar")))) -> 10.5 | K14: =F14 -> 10.5 | L14: =-F14 -> -10.5
A15: 8 | B15: 2400 | C15: 2401.6 | D15: =C15-B15 -> 1.6 | E15: 0.42 | F15: =IF(AND(B15>15,B15<=70),1,IF(AND(B15>70,B15<=300),B15*0.015,IF(AND(B15>300,B15<=1000),6,IF(AND(B15>1000),B15*0.005,"Revisar")))) -> 12 | K15: =F15 -> 12 | L15: =-F15 -> -12
A16: 9 | B16: 2700 | C16: 2701.8 | D16: =C16-B16 -> 1.8 | E16: 0.49 | F16: =IF(AND(B16>15,B16<=70),1,IF(AND(B16>70,B16<=300),B16*0.015,IF(AND(B16>300,B16<=1000),6,IF(AND(B16>1000),B16*0.005,"Revisar")))) -> 13.5 | K16: =F16 -> 13.5 | L16: =-F16 -> -13.5
A17: 10 | B17: 3000 | C17: 3001.8 | D17: =C17-B17 -> 1.8 | E17: 0.35 | F17: =IF(AND(B17>15,B17<=70),1,IF(AND(B17>70,B17<=300),B17*0.015,IF(AND(B17>300,B17<=1000),6,IF(AND(B17>1000),B17*0.005,"Revisar")))) -> 15 | K17: =F17 -> 15 | L17: =-F17 -> -15

Sheet VERIFICACIÓN CRYSTAL 1k
B2: INTRUMENTO | C2: MARCA | D2: MODELO | E2: SERIAL | F2: FECHA DE CALIBRACIÓN | G2: FECHA PROGRAMADA DE COMPROBACIÓN 1 | H2: FECHA PROGRAMADA DE COMPROBACIÓN 2 | I2: FECHA PROGRAMADA DE COMPROBACIÓN 3
B3: PATRÓN | C3: CRYSTAL | D3: =IF($C$3='CONTROL CALIBRACIONES'!$C$14,'CONTROL CALIBRACIONES'!E14,IF($C$3='CONTROL CALIBRACIONES'!$C$15,'CONTROL CALIBRACIONES'!E15,'CONTROL CALIBRACIONES'!E16)) -> XP2i | E3: =IF($C$3='CONTROL CALIBRACIONES'!$C$14,'CONTROL CALIBRACIONES'!F14,IF($C$3='CONTROL CALIBRACIONES'!$C$15,'CONTROL CALIBRACIONES'!F15,'CONTROL CALIBRACIONES'!F16)) -> 357309 | F3: ='CONTROL CALIBRACIONES'!G14 -> 45681 | G3: =IF(TODAY()-$F$3<=340,$F$4+90,"ERROR, CALIBRE EL PATRÓN") -> 45865 | H3: =IF(TODAY()-$F$3<=340,$F$4+180,"ERROR, CALIBRE EL PATRÓN") -> 45955 | I3: =IF(TODAY()-$F$3<=340,$F$4+270,"ERROR, CALIBRE EL PATRÓN") -> 46045
B4: INDICE BAJO VERIFICACIÓN (IBV) | C4: AMETEK CRYSTAL | D4: =IF(C4='CONTROL CALIBRACIONES'!C16,'CONTROL CALIBRACIONES'!E16,IF(C4='CONTROL CALIBRACIONES'!C16,'CONTROL CALIBRACIONES'!C16,'CONTROL CALIBRACIONES'!C17)) -> XP2i | E4: 322944 | F4: ='CONTROL CALIBRACIONES'!G18 -> 45775
B6: DATOS Y RESULTADOS DE LA CALIBRACIÓN
B8: VALOR PATRÓN (psi) | C8: VALOR IBV (psi) | D8: ERROR (psi) | E8: INCERTIDUMBRE | F8: Error permitido (+- psi) | G8: COMENTARIOS | H8: TEMPERATURA (°C) | I8: 20.5 | K8: Superior | L8: Inferior
A9: 2 | B9: 15 | C9: 15.061 | D9: =C9-B9 -> 0.061 | E9: 0.087 | F9: =IF(AND(B9>=15,B9<=70),1,IF(AND(B9>70,B9<=300),B9*0.015,IF(AND(B9>300,B9<=1000),6,IF(AND(B9>1000),B9*0.005,"Revisar")))) -> 1 | G9: =IF(AND(,D9>F9,D10>F10,D11>F11,D12>F12,D13>F13,D14>F14,D15>F15,D16>F16,D17>F17,D18>F18),"EQUIPO NO CUMPLE ESPECIFICACIÓN","EQUIPO CUMPLE ESPECIFICACIÓN") -> EQUIPO CUMPLE ESPECIFICACIÓN | H9: PRESIÓN ATMOSFERICA (hPa) | I9: 748.1 | K9: =F9 -> 1 | L9: =-F9 -> -1
A10: 3 | B10: 50 | C10: 50.086 | D10: =C10-B10 -> 0.086 | E10: 0.058 | F10: =IF(AND(B10>=15,B10<=70),1,IF(AND(B10>70,B10<=300),B10*0.015,IF(AND(B10>300,B10<=1000),6,IF(AND(B10>1000),B10*0.005,"Revisar")))) -> 1 | H10: HUMEDAD RELATIVA (%) | I10: 48.3 | K10: =F10 -> 1 | L10: =-F10 -> -1
A11: 4 | B11: 125 | C11: 125.086 | D11: =C11-B11 -> 0.086 | E11: 0.058 | F11: =IF(AND(B11>15,B11<=70),1,IF(AND(B11>70,B11<=300),B11*0.015,IF(AND(B11>300,B11<=1000),6,IF(AND(B11>1000),B11*0.005,"Revisar")))) -> 1.875 | H11: ENTE CERTIFICADOR | I11: Flexilatina | K11: =F11 -> 1.875 | L11: =-F11 -> -1.875
A12: 5 | B12: 250 | C12: 250.086 | D12: =C12-B12 -> 0.086 | E12: 0.059 | F12: =IF(AND(B12>15,B12<=70),1,IF(AND(B12>70,B12<=300),B12*0.015,IF(AND(B12>300,B12<=1000),6,IF(AND(B12>1000),B12*0.005,"Revisar")))) -> 3.75 | H12: FECHA DE CALIBRACIÓN | I12: 45775 | K12: =F12 -> 3.75 | L12: =-F12 -> -3.75
A13: 6 | B13: 375 | C13: 375.061 | D13: =C13-B13 -> 0.061 | E13: 0.089 | F13: =IF(AND(B13>15,B13<=70),1,IF(AND(B13>70,B13<=300),B13*0.015,IF(AND(B13>300,B13<=1000),6,IF(AND(B13>1000),B13*0.005,"Revisar")))) -> 6 | H13: Después de que el equipo llega, se confirma que calibrando con un tiempo calendario de 1 año, el equipo sigue cumpliendo con las especificaiones requeridas, por lo cual se mantiene el periodo de un año según lo establecido en la OIML 10 método 1 | K13: =F13 -> 6 | L13: =-F13 -> -6
A14: 7 | B14: 500 | C14: 500.111 | D14: =C14-B14 -> 0.111 | E14: 0.09 | F14: =IF(AND(B14>15,B14<=70),1,IF(AND(B14>70,B14<=300),B14*0.015,IF(AND(B14>300,B14<=1000),6,IF(AND(B14>1000),B14*0.005,"Revisar")))) -> 6 | K14: =F14 -> 6 | L14: =-F14 -> -6
A15: 8 | B15: 625 | C15: 625.161 | D15: =C15-B15 -> 0.161 | E15: 0.092 | F15: =IF(AND(B15>15,B15<=70),1,IF(AND(B15>70,B15<=300),B15*0.015,IF(AND(B15>300,B15<=1000),6,IF(AND(B15>1000),B15*0.005,"Revisar")))) -> 6 | K15: =F15 -> 6 | L15: =-F15 -> -6
A16: 9 | B16: 750 | C16: 750.186 | D16: =C16-B16 -> 0.186 | E16: 0.069 | F16: =IF(AND(B16>15,B16<=70),1,IF(AND(B16>70,B16<=300),B16*0.015,IF(AND(B16>300,B16<=1000),6,IF(AND(B16>1000),B16*0.005,"Revisar")))) -> 6 | K16: =F16 -> 6 | L16: =-F16 -> -6
A17: 10 | B17: 875 | C17: 875.186 | D17: =C17-B17 -> 0.186 | E17: 0.072 | F17: =IF(AND(B17>15,B17<=70),1,IF(AND(B17>70,B17<=300),B17*0.015,IF(AND(B17>300,B17<=1000),6,IF(AND(B17>1000),B17*0.005,"Revisar")))) -> 6 | K17: =F17 -> 6 | L17: =-F17 -> -6
A18: 11 | B18: 1000 | C18: 1000.186 | D18: =C18-B18 -> 0.186 | E18: 0.08 | F18: =IF(AND(B18>15,B18<=70),1,IF(AND(B18>70,B18<=300),B18*0.015,IF(AND(B18>300,B18<=1000),6,IF(AND(B18>1000),B18*0.005,"Revisar")))) -> 6 | K18: =F18 -> 6 | L18: =-F18 -> -6
B20: DATOS Y RESULTADOS DE LAS COMPROBACIONES
B21: Fecha | C21: 45861 | D21: 45951
B22: Responsable | C22: Andrés Felipe Ovalle | D22: Wilder Alberto Suarez
B23: VALOR PATRÓN (psi) | C23: VALOR COMPROBACIÓN 1 (psi) | D23: VALOR COMPROBACIÓN 2 (psi) | E23: VALOR COMPROBACIÓN 3 (psi) | G23: COMENTARIO COMPROBACIÓN 1 | H23: COMENTARIO COMPROBACIÓN 2 | J23: Superior | K23: Inferior
B24: 0 | C24: 0 | D24: 0 | G24: =IF(AND(ABS(G33)<$B$32,ABS(G34)<$B$33,ABS(G35)<$B$34,ABS(G36)<$B$35,ABS(G37)<$B$36,ABS(G38)<$B$37,ABS(G39)<$B$38,ABS(G40)<$B$39),"EQUIPO SE ENCUENTRA COMPROBADO","EQUIPO TIENE ALGUNA AFECTACIÓN, ENVIAR A REVISIÓN") -> EQUIPO SE ENCUENTRA COMPROBADO | H24: =IF(AND(ABS(H33)<$B$32,ABS(H34)<$B$33,ABS(H35)<$B$34,ABS(H36)<$B$35,ABS(H37)<$B$36,ABS(H38)<$B$37,ABS(H39)<$B$38,ABS(H40)<$B$39),"EQUIPO SE ENCUENTRA COMPROBADO","EQUIPO TIENE ALGUNA AFECTACIÓN, ENVIAR A REVISIÓN") -> #VALUE! | J24: =B33 -> 1 | K24: =-B33 -> -1
B25: 142 | C25: 142 | D25: 141.9 | J25: =B34 -> 2.13 | K25: =-B34 -> -2.13
B26: 284 | C26: 283.9 | D26: 283.9 | J26: =B35 -> 4.26 | K26: =-B35 -> -4.26
B27: 426 | C27: 425.9 | D27: 425.9 | J27: =B36 -> 6 | K27: =-B36 -> -6
B28: 568 | C28: 568 | D28: 568 | J28: =B37 -> 6 | K28: =-B37 -> -6
B29: 710 | C29: 709.9 | D29: 710 | J29: =B38 -> 6 | K29: =-B38 -> -6
B30: 852 | C30: 852.1 | D30: 852 | J30: =B39 -> 6 | K30: =-B39 -> -6
B31: 1000 | C31: 1000.1 | D31: 1000 | J31: =B40 -> 6 | K31: =-B40 -> -6
B32: Error Máximo permitido (psi) | C32: ERROR O | D32: ERROR 1 | E32: ERROR 2 | G32: DIFERENCIA ERROR 0-1 | H32: DIFERENCIA ERROR 0-2
B33: =IF(AND(B24>=15,B24<=70),1,IF(AND(B24>70,B24<=300),B24*0.015,IF(AND(B24>300,B24<=1000),6,IF(AND(B24>1000),B24*0.005,1)))) -> 1 | C33: =IF(C24="","",C24-B24) -> 0 | D33: =IF(D24="","",D24-B24) -> 0 | E33: =IF(E24="","",E24-B24) | G33: =C33-D33 -> 0 | H33: =C33-E33 -> #VALUE!
B34: =IF(AND(B25>=15,B25<=70),1,IF(AND(B25>70,B25<=300),B25*0.015,IF(AND(B25>300,B25<=1000),6,IF(AND(B25>1000),B25*0.005,1)))) -> 2.13 | C34: =IF(C25="","",C25-B25) -> 0 | D34: =IF(D25="","",D25-B25) -> -0.1 | E34: =IF(E25="","",E25-B25) | G34: =C34-D34 -> 0.1 | H34: =C34-E34 -> #VALUE!
B35: =IF(AND(B26>=15,B26<=70),1,IF(AND(B26>70,B26<=300),B26*0.015,IF(AND(B26>300,B26<=1000),6,IF(AND(B26>1000),B26*0.005,1)))) -> 4.26 | C35: =IF(C26="","",C26-B26) -> -0.1 | D35: =IF(D26="","",D26-B26) -> -0.1 | E35: =IF(E26="","",E26-B26) | G35: =C35-D35 -> 0 | H35: =C35-E35 -> #VALUE!
B36: =IF(AND(B27>=15,B27<=70),1,IF(AND(B27>70,B27<=300),B27*0.015,IF(AND(B27>300,B27<=1000),6,IF(AND(B27>1000),B27*0.005,1)))) -> 6 | C36: =IF(C27="","",C27-B27) -> -0.1 | D36: =IF(D27="","",D27-B27) -> -0.1 | E36: =IF(E27="","",E27-B27) | G36: =C36-D36 -> 0 | H36: =C36-E36 -> #VALUE!
B37: =IF(AND(B28>=15,B28<=70),1,IF(AND(B28>70,B28<=300),B28*0.015,IF(AND(B28>300,B28<=1000),6,IF(AND(B28>1000),B28*0.005,1)))) -> 6 | C37: =IF(C28="","",C28-B28) -> 0 | D37: =IF(D28="","",D28-B28) -> 0 | E37: =IF(E28="","",E28-B28) | G37: =C37-D37 -> 0 | H37: =C37-E37 -> #VALUE!
B38: =IF(AND(B29>=15,B29<=70),1,IF(AND(B29>70,B29<=300),B29*0.015,IF(AND(B29>300,B29<=1000),6,IF(AND(B29>1000),B29*0.005,1)))) -> 6 | C38: =IF(C29="","",C29-B29) -> -0.1 | D38: =IF(D29="","",D29-B29) -> 0 | E38: =IF(E29="","",E29-B29) | G38: =C38-D38 -> -0.1 | H38: =C38-E38 -> #VALUE!
B39: =IF(AND(B30>=15,B30<=70),1,IF(AND(B30>70,B30<=300),B30*0.015,IF(AND(B30>300,B30<=1000),6,IF(AND(B30>1000),B30*0.005,1)))) -> 6 | C39: =IF(C30="","",C30-B30) -> 0.1 | D39: =IF(D30="","",D30-B30) -> 0 | E39: =IF(E30="","",E30-B30) | G39: =C39-D39 -> 0.1 | H39: =C39-E39 -> #VALUE!
B40: =IF(AND(B31>=15,B31<=70),1,IF(AND(B31>70,B31<=300),B31*0.015,IF(AND(B31>300,B31<=1000),6,IF(AND(B31>1000),B31*0.005,1)))) -> 6 | C40: =IF(C31="","",C31-B31) -> 0.1 | D40: =IF(D31="","",D31-B31) -> 0 | E40: =IF(E31="","",E31-B31) | G40: =C40-D40 -> 0.1 | H40: =C40-E40 -> #VALUE!

Sheet VERIFICACIÓN CRYSTAL 5k
B2: INTRUMENTO | C2: MARCA | D2: MODELO | E2: SERIAL | F2: FECHA DE CALIBRACIÓN | G2: FECHA PROGRAMADA DE COMPROBACIÓN 1 | H2: FECHA PROGRAMADA DE COMPROBACIÓN 2 | I2: FECHA PROGRAMADA DE COMPROBACIÓN 3
B3: PATRÓN | C3: CRYSTAL | D3: =IF($C$3='CONTROL CALIBRACIONES'!$C$14,'CONTROL CALIBRACIONES'!E14,IF($C$3='CONTROL CALIBRACIONES'!$C$15,'CONTROL CALIBRACIONES'!E15,'CONTROL CALIBRACIONES'!E16)) -> XP2i | E3: =IF($C$3='CONTROL CALIBRACIONES'!$C$14,'CONTROL CALIBRACIONES'!F14,IF($C$3='CONTROL CALIBRACIONES'!$C$15,'CONTROL CALIBRACIONES'!F15,'CONTROL CALIBRACIONES'!F16)) -> 357309 | F3: ='CONTROL CALIBRACIONES'!G14 -> 45681 | G3: =IF(TODAY()-$F$3<=340,$F$4+90,"ERROR, CALIBRE EL PATRÓN") -> 45865 | H3: =IF(TODAY()-$F$3<=340,$F$4+180,"ERROR, CALIBRE EL PATRÓN") -> 45955 | I3: =IF(TODAY()-$F$3<=340,$F$4+270,"ERROR, CALIBRE EL PATRÓN") -> 46045
B4: INDICE BAJO VERIFICACIÓN (IBV) | C4: AMETEK CRYSTAL | D4: =IF(C4='CONTROL CALIBRACIONES'!C16,'CONTROL CALIBRACIONES'!E16,IF(C4='CONTROL CALIBRACIONES'!C16,'CONTROL CALIBRACIONES'!C16,'CONTROL CALIBRACIONES'!C17)) -> XP2i | E4: 322944 | F4: ='CONTROL CALIBRACIONES'!G18 -> 45775
B6: DATOS Y RESULTADOS DE LA CALIBRACIÓN
B8: VALOR PATRÓN (psi) | C8: VALOR IBV (psi) | D8: ERROR (psi) | E8: INCERTIDUMBRE | F8: Error permitido (+- psi) | G8: COMENTARIOS | H8: TEMPERATURA (°C) | I8: 21.4 | K8: Superior | L8: Inferior
A9: 1 | B9: 499.64 | C9: 500 | D9: =C9-B9 -> 0.36 | E9: 0.34 | F9: =IF(AND(B9>15,B9<=70),1,IF(AND(B9>70,B9<=300),B9*0.015,IF(AND(B9>300,B9<=1000),6,IF(AND(B9>1000),B9*0.005,"Revisar")))) -> 6 | G9: =IF(AND(,D9>F9,D10>F10,D11>F11,D12>F12,D13>F13,D14>F14,D15>F15,D16>F16,D17>F17,D18>F18),"EQUIPO NO CUMPLE ESPECIFICACIÓN","EQUIPO CUMPLE ESPECIFICACIÓN") -> EQUIPO CUMPLE ESPECIFICACIÓN | H9: PRESIÓN ATMOSFERICA (hPa) | I9: 753.4 | K9: =F9 -> 6 | L9: =-F9 -> -6
A10: 2 | B10: 999.56 | C10: 1000 | D10: =C10-B10 -> 0.44 | E10: 0.34 | F10: =IF(AND(B10>15,B10<=70),1,IF(AND(B10>70,B10<=300),B10*0.015,IF(AND(B10>300,B10<=1000),6,IF(AND(B10>1000),B10*0.005,"Revisar")))) -> 6 | H10: HUMEDAD RELATIVA (%) | I10: 57.9 | K10: =F10 -> 6 | L10: =-F10 -> -6
A11: 3 | B11: 1499.59 | C11: 1500 | D11: =C11-B11 -> 0.41 | E11: 0.34 | F11: =IF(AND(B11>15,B11<=70),1,IF(AND(B11>70,B11<=300),B11*0.015,IF(AND(B11>300,B11<=1000),6,IF(AND(B11>1000),B11*0.005,"Revisar")))) -> 7.49795 | H11: ENTE CERTIFICADOR | I11: Metrology | K11: =F11 -> 7.49795 | L11: =-F11 -> -7.49795
A12: 4 | B12: 1999.82 | C12: 2000 | D12: =C12-B12 -> 0.18 | E12: 0.34 | F12: =IF(AND(B12>15,B12<=70),1,IF(AND(B12>70,B12<=300),B12*0.015,IF(AND(B12>300,B12<=1000),6,IF(AND(B12>1000),B12*0.005,"Revisar")))) -> 9.9991 | H12: FECHA DE CALIBRACIÓN | I12: 45628 | K12: =F12 -> 9.9991 | L12: =-F12 -> -9.9991
A13: 5 | B13: 2499.35 | C13: 2500 | D13: =C13-B13 -> 0.65 | E13: 0.34 | F13: =IF(AND(B13>15,B13<=70),1,IF(AND(B13>70,B13<=300),B13*0.015,IF(AND(B13>300,B13<=1000),6,IF(AND(B13>1000),B13*0.005,"Revisar")))) -> 12.49675 | H13: Después de que el equipo llega, se confirma que calibrando con un tiempo calendario de 1 año, el equipo sigue cumpliendo con las especificaiones requeridas, por lo cual se mantiene el periodo de un año según lo establecido en la OIML 10 método 1 | K13: =F13 -> 12.49675 | L13: =-F13 -> -12.49675
A14: 6 | B14: 2999.58 | C14: 3000 | D14: =C14-B14 -> 0.42 | E14: 0.34 | F14: =IF(AND(B14>15,B14<=70),1,IF(AND(B14>70,B14<=300),B14*0.015,IF(AND(B14>300,B14<=1000),6,IF(AND(B14>1000),B14*0.005,"Revisar")))) -> 14.9979 | K14: =F14 -> 14.9979 | L14: =-F14 -> -14.9979
A15: 7 | B15: 3499.2 | C15: 3500 | D15: =C15-B15 -> 0.8 | E15: 0.34 | F15: =IF(AND(B15>15,B15<=70),1,IF(AND(B15>70,B15<=300),B15*0.015,IF(AND(B15>300,B15<=1000),6,IF(AND(B15>1000),B15*0.005,"Revisar")))) -> 17.496 | K15: =F15 -> 17.496 | L15: =-F15 -> -17.496
A16: 8 | B16: 3999.43 | C16: 4000 | D16: =C16-B16 -> 0.57 | E16: 0.35 | F16: =IF(AND(B16>15,B16<=70),1,IF(AND(B16>70,B16<=300),B16*0.015,IF(AND(B16>300,B16<=1000),6,IF(AND(B16>1000),B16*0.005,"Revisar")))) -> 19.99715 | K16: =F16 -> 19.99715 | L16: =-F16 -> -19.99715
A17: 9 | B17: 4499.04 | C17: 4500 | D17: =C17-B17 -> 0.96 | E17: 0.35 | F17: =IF(AND(B17>15,B17<=70),1,IF(AND(B17>70,B17<=300),B17*0.015,IF(AND(B17>300,B17<=1000),6,IF(AND(B17>1000),B17*0.005,"Revisar")))) -> 22.4952 | K17: =F17 -> 22.4952 | L17: =-F17 -> -22.4952
A18: 10 | B18: 4999.54 | C18: 5000 | D18: =C18-B18 -> 0.46 | E18: 0.35 | F18: =IF(AND(B18>15,B18<=70),1,IF(AND(B18>70,B18<=300),B18*0.015,IF(AND(B18>300,B18<=1000),6,IF(AND(B18>1000),B18*0.005,"Revisar")))) -> 24.9977 | K18: =F18 -> 24.9977 | L18: =-F18 -> -24.9977
B20: DATOS Y RESULTADOS DE LAS COMPROBACIONES
B21: Fecha | C21: 45720 | D21: 45811 | E21: 45897
B22: Responsable | C22: Andrés Felipe Ovalle | D22: Carlos Alberto Suarez | E22: Andrés Felipe Ovalle
B23: VALOR PATRÓN (psi) | C23: VALOR COMPROBACIÓN 1 (psi) | D23: VALOR COMPROBACIÓN 2 (psi) | E23: VALOR COMPROBACIÓN 3 (psi) | G23: COMENTARIO COMPROBACIÓN 1 | H23: COMENTARIO COMPROBACIÓN 2 | J23: Superior | K23: Inferior
B24: 0 | C24: 0 | D24: 0 | G24: =IF(AND(ABS(G33)<$B$32,ABS(G34)<$B$33,ABS(G35)<$B$34,ABS(G36)<$B$35,ABS(G37)<$B$36,ABS(G38)<$B$37,ABS(G39)<$B$38,ABS(G40)<$B$39),"EQUIPO SE ENCUENTRA COMPROBADO","EQUIPO TIENE ALGUNA AFECTACIÓN, ENVIAR A REVISIÓN") -> EQUIPO SE ENCUENTRA COMPROBADO | H24: =IF(AND(ABS(H33)<$B$32,ABS(H34)<$B$33,ABS(H35)<$B$34,ABS(H36)<$B$35,ABS(H37)<$B$36,ABS(H38)<$B$37,ABS(H39)<$B$38,ABS(H40)<$B$39),"EQUIPO SE ENCUENTRA COMPROBADO","EQUIPO TIENE ALGUNA AFECTACIÓN, ENVIAR A REVISIÓN") -> #VALUE! | J24: =B33 -> 1 | K24: =-B33 -> -1
B25: 428 | C25: 427.7 | D25: 427.8 | J25: =B34 -> 6 | K25: =-B34 -> -6
B26: 856 | C26: 855.9 | D26: 855.8 | J26: =B35 -> 6 | K26: =-B35 -> -6
B27: 1284 | C27: 1283.9 | D27: 1283.8 | J27: =B36 -> 6.42 | K27: =-B36 -> -6.42
B28: 1712 | C28: 1711.4 | D28: 1711.6 | J28: =B37 -> 8.56 | K28: =-B37 -> -8.56
B29: 2140 | C29: 2140.4 | D29: 2140.5 | J29: =B38 -> 10.7 | K29: =-B38 -> -10.7
B30: 2568 | C30: 2566.2 | D30: 2566.5 | J30: =B39 -> 12.84 | K30: =-B39 -> -12.84
B31: 3000 | C31: 3000.2 | D31: 3000.3 | J31: =B40 -> 15 | K31: =-B40 -> -15
B32: Error Máximo permitido (psi) | C32: ERROR O | D32: ERROR 1 | E32: ERROR 2 | G32: DIFERENCIA ERROR 0-1 | H32: DIFERENCIA ERROR 0-2
B33: =IF(AND(B24>=15,B24<=70),1,IF(AND(B24>70,B24<=300),B24*0.015,IF(AND(B24>300,B24<=1000),6,IF(AND(B24>1000),B24*0.005,1)))) -> 1 | C33: =C24-B24 -> 0 | D33: =D24-B24 -> 0 | E33: =IF(E24="","",E24-B24) | G33: =C33-D33 -> 0 | H33: =C33-E33 -> #VALUE!
B34: =IF(AND(B25>=15,B25<=70),1,IF(AND(B25>70,B25<=300),B25*0.015,IF(AND(B25>300,B25<=1000),6,IF(AND(B25>1000),B25*0.005,1)))) -> 6 | C34: =C25-B25 -> -0.3 | D34: =D25-B25 -> -0.2 | E34: =IF(E25="","",E25-B25) | G34: =C34-D34 -> -0.1 | H34: =C34-E34 -> #VALUE!
B35: =IF(AND(B26>=15,B26<=70),1,IF(AND(B26>70,B26<=300),B26*0.015,IF(AND(B26>300,B26<=1000),6,IF(AND(B26>1000),B26*0.005,1)))) -> 6 | C35: =C26-B26 -> -0.1 | D35: =D26-B26 -> -0.2 | E35: =IF(E26="","",E26-B26) | G35: =C35-D35 -> 0.1 | H35: =C35-E35 -> #VALUE!
B36: =IF(AND(B27>=15,B27<=70),1,IF(AND(B27>70,B27<=300),B27*0.015,IF(AND(B27>300,B27<=1000),6,IF(AND(B27>1000),B27*0.005,1)))) -> 6.42 | C36: =C27-B27 -> -0.1 | D36: =D27-B27 -> -0.2 | E36: =IF(E27="","",E27-B27) | G36: =C36-D36 -> 0.1 | H36: =C36-E36 -> #VALUE!
B37: =IF(AND(B28>=15,B28<=70),1,IF(AND(B28>70,B28<=300),B28*0.015,IF(AND(B28>300,B28<=1000),6,IF(AND(B28>1000),B28*0.005,1)))) -> 8.56 | C37: =C28-B28 -> -0.6 | D37: =D28-B28 -> -0.4 | E37: =IF(E28="","",E28-B28) | G37: =C37-D37 -> -0.2 | H37: =C37-E37 -> #VALUE!
B38: =IF(AND(B29>=15,B29<=70),1,IF(AND(B29>70,B29<=300),B29*0.015,IF(AND(B29>300,B29<=1000),6,IF(AND(B29>1000),B29*0.005,1)))) -> 10.7 | C38: =C29-B29 -> 0.4 | D38: =D29-B29 -> 0.5 | E38: =IF(E29="","",E29-B29) | G38: =C38-D38 -> -0.1 | H38: =C38-E38 -> #VALUE!
B39: =IF(AND(B30>=15,B30<=70),1,IF(AND(B30>70,B30<=300),B30*0.015,IF(AND(B30>300,B30<=1000),6,IF(AND(B30>1000),B30*0.005,1)))) -> 12.84 | C39: =C30-B30 -> -1.8 | D39: =D30-B30 -> -1.5 | E39: =IF(E30="","",E30-B30) | G39: =C39-D39 -> -0.3 | H39: =C39-E39 -> #VALUE!
B40: =IF(AND(B31>=15,B31<=70),1,IF(AND(B31>70,B31<=300),B31*0.015,IF(AND(B31>300,B31<=1000),6,IF(AND(B31>1000),B31*0.005,1)))) -> 15 | C40: =C31-B31 -> 0.2 | D40: =D31-B31 -> 0.3 | E40: =IF(E31="","",E31-B31) | G40: =C40-D40 -> -0.1 | H40: =C40-E40 -> #VALUE!

Sheet VERIFICACIÓN ADDITEL
B2: INTRUMENTO | C2: MARCA | D2: MODELO | E2: SERIAL | F2: FECHA DE CALIBRACIÓN | G2: FECHA PROGRAMADA DE COMPROBACIÓN 1 | H2: FECHA PROGRAMADA DE COMPROBACIÓN 2 | I2: FECHA PROGRAMADA DE COMPROBACIÓN 3
B3: PATRÓN | C3: CRYSTAL | D3: =IF($C$3='CONTROL CALIBRACIONES'!$C$14,'CONTROL CALIBRACIONES'!E14,IF($C$3='CONTROL CALIBRACIONES'!$C$15,'CONTROL CALIBRACIONES'!E15,'CONTROL CALIBRACIONES'!E16)) -> XP2i | E3: =IF($C$3='CONTROL CALIBRACIONES'!$C$14,'CONTROL CALIBRACIONES'!F14,IF($C$3='CONTROL CALIBRACIONES'!$C$15,'CONTROL CALIBRACIONES'!F15,'CONTROL CALIBRACIONES'!F16)) -> 357309 | F3: ='CONTROL CALIBRACIONES'!G14 -> 45681 | G3: =IF(TODAY()-$F$3<=340,$F$4+90,"ERROR, CALIBRE EL PATRÓN") -> 45865 | H3: =IF(TODAY()-$F$3<=340,$F$4+180,"ERROR, CALIBRE EL PATRÓN") -> 45955 | I3: =IF(TODAY()-$F$3<=340,$F$4+270,"ERROR, CALIBRE EL PATRÓN") -> 46045
B4: INDICE BAJO VERIFICACIÓN (IBV) | C4: AMETEK CRYSTAL | D4: =IF(C4='CONTROL CALIBRACIONES'!C16,'CONTROL CALIBRACIONES'!E16,IF(C4='CONTROL CALIBRACIONES'!C16,'CONTROL CALIBRACIONES'!C16,'CONTROL CALIBRACIONES'!C17)) -> XP2i | E4: 322944 | F4: ='CONTROL CALIBRACIONES'!G18 -> 45775
B6: DATOS Y RESULTADOS DE LA CALIBRACIÓN
B8: VALOR PATRÓN (psi) | C8: VALOR IBV (psi) | D8: ERROR (psi) | E8: INCERTIDUMBRE | F8: Error permitido (+- psi) | G8: COMENTARIOS | H8: TEMPERATURA (°C) | I8: 23.2 | K8: Superior | L8: Inferior
A9: 1 | B9: 300 | C9: 299.8 | D9: =C9-B9 -> -0.2 | E9: 0.34 | F9: =IF(AND(B9>15,B9<=70),1,IF(AND(B9>70,B9<=300),B9*0.015,IF(AND(B9>300,B9<=1000),6,IF(AND(B9>1000),B9*0.005,"Revisar")))) -> 4.5 | G9: =IF(AND(,D9>F9,D10>F10,D11>F11,D12>F12,D13>F13,D14>F14,D15>F15,D16>F16,D17>F17,D18>F18),"EQUIPO NO CUMPLE ESPECIFICACIÓN","EQUIPO CUMPLE ESPECIFICACIÓN") -> EQUIPO CUMPLE ESPECIFICACIÓN | H9: PRESIÓN ATMOSFERICA (hPa) | I9: 751.1 | K9: =F9 -> 4.5 | L9: =-F9 -> -4.5
A10: 2 | B10: 600 | C10: 600.2 | D10: =C10-B10 -> 0.2 | E10: 0.34 | F10: =IF(AND(B10>15,B10<=70),1,IF(AND(B10>70,B10<=300),B10*0.015,IF(AND(B10>300,B10<=1000),6,IF(AND(B10>1000),B10*0.005,"Revisar")))) -> 6 | H10: HUMEDAD RELATIVA (%) | I10: 49.4 | K10: =F10 -> 6 | L10: =-F10 -> -6
A11: 3 | B11: 900 | C11: 899.9 | D11: =C11-B11 -> -0.1 | E11: 0.34 | F11: =IF(AND(B11>15,B11<=70),1,IF(AND(B11>70,B11<=300),B11*0.015,IF(AND(B11>300,B11<=1000),6,IF(AND(B11>1000),B11*0.005,"Revisar")))) -> 6 | H11: ENTE CERTIFICADOR | I11: Metrology | K11: =F11 -> 6 | L11: =-F11 -> -6
A12: 4 | B12: 1200 | C12: 1199.8 | D12: =C12-B12 -> -0.2 | E12: 0.34 | F12: =IF(AND(B12>15,B12<=70),1,IF(AND(B12>70,B12<=300),B12*0.015,IF(AND(B12>300,B12<=1000),6,IF(AND(B12>1000),B12*0.005,"Revisar")))) -> 6 | H12: FECHA DE CALIBRACIÓN | I12: 45635 | K12: =F12 -> 6 | L12: =-F12 -> -6
A13: 5 | B13: 1500 | C13: 1499.8 | D13: =C13-B13 -> -0.2 | E13: 0.34 | F13: =IF(AND(B13>15,B13<=70),1,IF(AND(B13>70,B13<=300),B13*0.015,IF(AND(B13>300,B13<=1000),6,IF(AND(B13>1000),B13*0.005,"Revisar")))) -> 7.5 | H13: Después de que el equipo llega, se confirma que calibrando con un tiempo calendario de 1 año, el equipo sigue cumpliendo con las especificaiones requeridas, por lo cual se mantiene el periodo de un año según lo establecido en la OIML 10 método 1 | K13: =F13 -> 7.5 | L13: =-F13 -> -7.5
A14: 6 | B14: 1800 | C14: 1800 | D14: =C14-B14 -> 0 | E14: 0.34 | F14: =IF(AND(B14>15,B14<=70),1,IF(AND(B14>70,B14<=300),B14*0.015,IF(AND(B14>300,B14<=1000),6,IF(AND(B14>1000),B14*0.005,"Revisar")))) -> 9 | K14: =F14 -> 9 | L14: =-F14 -> -9
A15: 7 | B15: 2100 | C15: 2100.4 | D15: =C15-B15 -> 0.4 | E15: 0.34 | F15: =IF(AND(B15>15,B15<=70),1,IF(AND(B15>70,B15<=300),B15*0.015,IF(AND(B15>300,B15<=1000),6,IF(AND(B15>1000),B15*0.005,"Revisar")))) -> 10.5 | K15: =F15 -> 10.5 | L15: =-F15 -> -10.5
A16: 8 | B16: 2400 | C16: 2399.9 | D16: =C16-B16 -> -0.1 | E16: 0.35 | F16: =IF(AND(B16>15,B16<=70),1,IF(AND(B16>70,B16<=300),B16*0.015,IF(AND(B16>300,B16<=1000),6,IF(AND(B16>1000),B16*0.005,"Revisar")))) -> 12 | K16: =F16 -> 12 | L16: =-F16 -> -12
A17: 9 | B17: 2700 | C17: 2699.9 | D17: =C17-B17 -> -0.1 | E17: 0.35 | F17: =IF(AND(B17>15,B17<=70),1,IF(AND(B17>70,B17<=300),B17*0.015,IF(AND(B17>300,B17<=1000),6,IF(AND(B17>1000),B17*0.005,"Revisar")))) -> 13.5 | K17: =F17 -> 13.5 | L17: =-F17 -> -13.5
A18: 10 | B18: 3000 | C18: 2999.7 | D18: =C18-B18 -> -0.3 | E18: 0.35 | F18: =IF(AND(B18>15,B18<=70),1,IF(AND(B18>70,B18<=300),B18*0.015,IF(AND(B18>300,B18<=1000),6,IF(AND(B18>1000),B18*0.005,"Revisar")))) -> 15 | K18: =F18 -> 15 | L18: =-F18 -> -15
B20: DATOS Y RESULTADOS DE LAS COMPROBACIONES
B21: Fecha | D21: 45834 | E21: 45929
B22: Responsable | D22: Andrés Felipe Ovalle | E22: Andrés Felipe Ovalle
B23: VALOR PATRÓN (psi) | C23: VALOR COMPROBACIÓN 1 (psi) | D23: VALOR COMPROBACIÓN 2 (psi) | E23: VALOR COMPROBACIÓN 3 (psi) | G23: COMENTARIO COMPROBACIÓN 1 | H23: COMENTARIO COMPROBACIÓN 2 | J23: Superior | K23: Inferior
B24: 0 | C24: 0 | D24: 0 | E24: 0 | G24: =IF(AND(ABS(G33)<$B$32,ABS(G34)<$B$33,ABS(G35)<$B$34,ABS(G36)<$B$35,ABS(G37)<$B$36,ABS(G38)<$B$37,ABS(G39)<$B$38,ABS(G40)<$B$39),"EQUIPO SE ENCUENTRA COMPROBADO","EQUIPO TIENE ALGUNA AFECTACIÓN, ENVIAR A REVISIÓN") -> EQUIPO SE ENCUENTRA COMPROBADO | H24: =IF(AND(ABS(H33)<$B$32,ABS(H34)<$B$33,ABS(H35)<$B$34,ABS(H36)<$B$35,ABS(H37)<$B$36,ABS(H38)<$B$37,ABS(H39)<$B$38,ABS(H40)<$B$39),"EQUIPO SE ENCUENTRA COMPROBADO","EQUIPO TIENE ALGUNA AFECTACIÓN, ENVIAR A REVISIÓN") -> EQUIPO SE ENCUENTRA COMPROBADO | I24: 0 | J24: =B33 -> 1 | K24: =-B33 -> -1
B25: 428 | C25: 427.9 | D25: 427.9 | E25: 427.9 | I25: 428 | J25: =B34 -> 6 | K25: =-B34 -> -6
B26: 856 | C26: 855.9 | D26: 855.9 | E26: 856 | I26: 856 | J26: =B35 -> 6 | K26: =-B35 -> -6
B27: 1284 | C27: 1284.1 | D27: 1284.1 | E27: 1284.1 | I27: 1284 | J27: =B36 -> 6.42 | K27: =-B36 -> -6.42
B28: 1712 | C28: 1712.1 | D28: 1712.1 | E28: 1712.2 | I28: 1712.1 | J28: =B37 -> 8.56 | K28: =-B37 -> -8.56
B29: 2140 | C29: 2140.2 | D29: 2140.2 | E29: 2140.2 | I29: 2140.2 | J29: =B38 -> 10.7 | K29: =-B38 -> -10.7
B30: 2568 | C30: 2568.3 | D30: 2568.3 | E30: 2568.3 | I30: 2568.3 | J30: =B39 -> 12.84 | K30: =-B39 -> -12.84
B31: 3000 | C31: 3000.6 | D31: 3000.6 | E31: 3000.5 | I31: 3000.4 | J31: =B40 -> 15 | K31: =-B40 -> -15
B32: Error Máximo permitido (psi) | C32: ERROR O | D32: ERROR 1 | E32: ERROR 2 | G32: DIFERENCIA ERROR 0-1 | H32: DIFERENCIA ERROR 0-2
B33: =IF(AND(B24>=15,B24<=70),1,IF(AND(B24>70,B24<=300),B24*0.015,IF(AND(B24>300,B24<=1000),6,IF(AND(B24>1000),B24*0.005,1)))) -> 1 | C33: =C24-B24 -> 0 | D33: =D24-B24 -> 0 | E33: =IF(E24="","",E24-B24) -> 0 | G33: =C33-D33 -> 0 | H33: =C33-E33 -> 0
B34: =IF(AND(B25>=15,B25<=70),1,IF(AND(B25>70,B25<=300),B25*0.015,IF(AND(B25>300,B25<=1000),6,IF(AND(B25>1000),B25*0.005,1)))) -> 6 | C34: =C25-B25 -> -0.1 | D34: =D25-B25 -> -0.1 | E34: =IF(E25="","",E25-B25) -> -0.1 | G34: =C34-D34 -> 0 | H34: =C34-E34 -> 0
B35: =IF(AND(B26>=15,B26<=70),1,IF(AND(B26>70,B26<=300),B26*0.015,IF(AND(B26>300,B26<=1000),6,IF(AND(B26>1000),B26*0.005,1)))) -> 6 | C35: =C26-B26 -> -0.1 | D35: =D26-B26 -> -0.1 | E35: =IF(E26="","",E26-B26) -> 0 | G35: =C35-D35 -> 0 | H35: =C35-E35 -> -0.1
B36: =IF(AND(B27>=15,B27<=70),1,IF(AND(B27>70,B27<=300),B27*0.015,IF(AND(B27>300,B27<=1000),6,IF(AND(B27>1000),B27*0.005,1)))) -> 6.42 | C36: =C27-B27 -> 0.1 | D36: =D27-B27 -> 0.1 | E36: =IF(E27="","",E27-B27) -> 0.1 | G36: =C36-D36 -> 0 | H36: =C36-E36 -> 0
B37: =IF(AND(B28>=15,B28<=70),1,IF(AND(B28>70,B28<=300),B28*0.015,IF(AND(B28>300,B28<=1000),6,IF(AND(B28>1000),B28*0.005,1)))) -> 8.56 | C37: =C28-B28 -> 0.1 | D37: =D28-B28 -> 0.1 | E37: =IF(E28="","",E28-B28) -> 0.2 | G37: =C37-D37 -> 0 | H37: =C37-E37 -> -0.1
B38: =IF(AND(B29>=15,B29<=70),1,IF(AND(B29>70,B29<=300),B29*0.015,IF(AND(B29>300,B29<=1000),6,IF(AND(B29>1000),B29*0.005,1)))) -> 10.7 | C38: =C29-B29 -> 0.2 | D38: =D29-B29 -> 0.2 | E38: =IF(E29="","",E29-B29) -> 0.2 | G38: =C38-D38 -> 0 | H38: =C38-E38 -> 0
B39: =IF(AND(B30>=15,B30<=70),1,IF(AND(B30>70,B30<=300),B30*0.015,IF(AND(B30>300,B30<=1000),6,IF(AND(B30>1000),B30*0.005,1)))) -> 12.84 | C39: =C30-B30 -> 0.3 | D39: =D30-B30 -> 0.3 | E39: =IF(E30="","",E30-B30) -> 0.3 | G39: =C39-D39 -> 0 | H39: =C39-E39 -> 0
B40: =IF(AND(B31>=15,B31<=70),1,IF(AND(B31>70,B31<=300),B31*0.015,IF(AND(B31>300,B31<=1000),6,IF(AND(B31>1000),B31*0.005,1)))) -> 15 | C40: =C31-B31 -> 0.6 | D40: =D31-B31 -> 0.6 | E40: =IF(E31="","",E31-B31) -> 0.5 | G40: =C40-D40 -> 0 | H40: =C40-E40 -> 0.1

Sheet VERIFICACIÓN DANFOSS 870 
B2: INTRUMENTO | C2: MARCA | D2: MODELO | E2: SERIAL | F2: FECHA DE CALIBRACIÓN | G2: FECHA PROGRAMADA PARA REGISTRO INICIAL | H2: FECHA PROGRAMADA COMPROBACIÓN 1 | I2: FECHA PROGRAMADA COMPROBACIÓN 2
B3: PATRÓN | C3: CRYSTAL | D3: =IF($C$3='CONTROL CALIBRACIONES'!$C$14,'CONTROL CALIBRACIONES'!E14,IF($C$3='CONTROL CALIBRACIONES'!$C$15,'CONTROL CALIBRACIONES'!E15,'CONTROL CALIBRACIONES'!E16)) -> XP2i | E3: =IF($C$3='CONTROL CALIBRACIONES'!$C$14,'CONTROL CALIBRACIONES'!F14,IF($C$3='CONTROL CALIBRACIONES'!$C$15,'CONTROL CALIBRACIONES'!F15,'CONTROL CALIBRACIONES'!F16)) -> 357309 | F3: ='CONTROL CALIBRACIONES'!G14 -> 45681 | G3: =F4+5 -> 45906 | H3: =IF(TODAY()-$F$3<=340,$F$4+120,"ERROR, CALIBRE EL PATRÓN") -> 46021 | I3: =IF(TODAY()-$F$3<=340,$F$4+240,"ERROR, CALIBRE EL PATRÓN") -> 46141
B4: INDICE BAJO VERIFICACIÓN (IBV) | C4: DANFOSS | D4: MBS3000 | E4: 051950519282 | F4: ='CONTROL CALIBRACIONES'!G32 -> 45901
B6: DATOS Y RESULTADOS DE LA CALIBRACIÓN
B8: VALOR PATRÓN (psi) | C8: VALOR IBV (psi) | D8: ERROR (PSI) | E8: INCERTIDUMBRE | F8: Error máximo permitido (±psi) | G8: COMENTARIOS | H8: TEMPERATURA (°C) | I8: 20.3 | K8: Superior | L8: Inferior
A9: 1 | B9: 0 | C9: 0 | D9: =B9-C9 -> 0 | E9: 0.0064 | F9: 0.1 | G9: =IF(AND(ABS(D9)<F9,ABS(D10)<F10,ABS(D11)<F11,ABS(D12)<F12,ABS(D13)<F13,ABS(D14)<F14,ABS(D15)<F15,ABS(D16)<F16,ABS(D17)<F17,ABS(D18)<F18,ABS(D19)<F19),"EQUIPO CUMPLE ESPECIFICACIÓN","EQUIPO NO CUMPLE ESPECIFICACIÓN") -> EQUIPO CUMPLE ESPECIFICACIÓN | H9: PRESIÓN ATMOSFERICA (hPa) | I9: 747 | K9: =F9 -> 0.1 | L9: =-F9 -> -0.1
A10: 2 | B10: 15 | C10: 14.8697 | D10: =B10-C10 -> 0.1303 | E10: 0.0064 | F10: =IF(AND(B10>=15,B10<=70),2,IF(AND(B10>70,B10<=300),B10*0.03,IF(AND(B10>300,B10<=1000),12,IF(AND(B10>1000),B10*0.01,"Revisar")))) -> 2 | H10: HUMEDAD RELATIVA (%) | I10: 0.652 | K10: =F10 -> 2 | L10: =-F10 -> -2
A11: 3 | B11: 70 | C11: 69.8297 | D11: =B11-C11 -> 0.1703 | E11: 0.0073 | F11: =IF(AND(B11>=15,B11<=70),2,IF(AND(B11>70,B11<=300),B11*0.03,IF(AND(B11>300,B11<=1000),12,IF(AND(B11>1000),B11*0.01,"Revisar")))) -> 2 | H11: ENTE CERTIFICADOR | I11: Flexilatina | K11: =F11 -> 2 | L11: =-F11 -> -2
A12: 4 | B12: 108 | C12: 107.8197 | D12: =B12-C12 -> 0.1803 | E12: 0.0086 | F12: =IF(AND(B12>=15,B12<=70),2,IF(AND(B12>70,B12<=300),B12*0.03,IF(AND(B12>300,B12<=1000),12,IF(AND(B12>1000),B12*0.01,"Revisar")))) -> 3.24 | H12: FECHA DE CALIBRACIÓN | I12: =F4 -> 45901 | K12: =F12 -> 3.24 | L12: =-F12 -> -3.24
A13: 5 | B13: 216 | C13: 215.84 | D13: =B13-C13 -> 0.16 | E13: 0.017 | F13: =IF(AND(B13>=15,B13<=70),2,IF(AND(B13>70,B13<=300),B13*0.03,IF(AND(B13>300,B13<=1000),12,IF(AND(B13>1000),B13*0.01,"Revisar")))) -> 6.48 | H13: Después de que el equipo llega, se confirma que calibrando con un tiempo calendario de 1 año, el equipo sigue cumpliendo con las especificaiones requeridas, por lo cual se mantiene el periodo de un año según lo establecido en la OIML 10 método 1 | K13: =F13 -> 6.48 | L13: =-F13 -> -6.48
A14: 6 | B14: 324 | C14: 323.87 | D14: =B14-C14 -> 0.13 | E14: 0.026 | F14: =IF(AND(B14>=15,B14<=70),2,IF(AND(B14>70,B14<=300),B14*0.03,IF(AND(B14>300,B14<=1000),12,IF(AND(B14>1000),B14*0.01,"Revisar")))) -> 12 | K14: =F14 -> 12 | L14: =-F14 -> -12
A15: 7 | B15: 432 | C15: 431.75 | D15: =B15-C15 -> 0.25 | E15: 0.035 | F15: =IF(AND(B15>=15,B15<=70),2,IF(AND(B15>70,B15<=300),B15*0.03,IF(AND(B15>300,B15<=1000),12,IF(AND(B15>1000),B15*0.01,"Revisar")))) -> 12 | K15: =F15 -> 12 | L15: =-F15 -> -12
A16: 8 | B16: 540 | C16: 539.63 | D16: =B16-C16 -> 0.37 | E16: 0.043 | F16: =IF(AND(B16>=15,B16<=70),2,IF(AND(B16>70,B16<=300),B16*0.03,IF(AND(B16>300,B16<=1000),12,IF(AND(B16>1000),B16*0.01,"Revisar")))) -> 12 | K16: =F16 -> 12 | L16: =-F16 -> -12
A17: 9 | B17: 648 | C17: 647.22 | D17: =B17-C17 -> 0.78 | E17: 0.052 | F17: =IF(AND(B17>=15,B17<=70),2,IF(AND(B17>70,B17<=300),B17*0.03,IF(AND(B17>300,B17<=1000),12,IF(AND(B17>1000),B17*0.01,"Revisar")))) -> 12 | K17: =F17 -> 12 | L17: =-F17 -> -12
A18: 10 | B18: 756 | C18: 754.66 | D18: =B18-C18 -> 1.34 | E18: 0.06 | F18: =IF(AND(B18>=15,B18<=70),2,IF(AND(B18>70,B18<=300),B18*0.03,IF(AND(B18>300,B18<=1000),12,IF(AND(B18>1000),B18*0.01,"Revisar")))) -> 12 | K18: =F18 -> 12 | L18: =-F18 -> -12
A19: 11 | B19: 870 | C19: 868.05 | D19: =B19-C19 -> 1.95 | E19: 0.07 | F19: =IF(AND(B19>=15,B19<=70),2,IF(AND(B19>70,B19<=300),B19*0.03,IF(AND(B19>300,B19<=1000),12,IF(AND(B19>1000),B19*0.01,"Revisar")))) -> 12 | K19: =F19 -> 12 | L19: =-F19 -> -12
B21: DATOS Y RESULTADOS DE LAS COMPROBACIONES
B22: Fecha | C22: 45911 | D22: 45924
B23: Responsable | C23: Andrés Felipe Ovalle | D23: Andrés Felipe Ovalle
B24: VALOR PATRÓN (psi) | C24: VALOR REGISTRO INICIAL (psi) | D24: VALOR COMPROBACIÓN 1 (psi) | E24: VALOR COMPROBACIÓN 2 (psi) | G24: COMENTARIO COMPROBACIÓN 1 | H24: COMENTARIO COMPROBACIÓN 2 | J24: Superior | K24: Inferior
B25: 0 | C25: 0.01 | D25: 0 | G25: =IF(AND(ABS(G34)<$B$34,ABS(G35)<$B$35,ABS(G36)<$B$36,ABS(G37)<$B$37,ABS(G38)<$B$38,ABS(G39)<$B$39,ABS(G40)<$B$40,ABS(G41)<$B$41),"EQUIPO SE ENCUENTRA COMPROBADO","EQUIPO TIENE ALGUNA AFECTACIÓN, ENVIAR A REVISIÓN") -> EQUIPO SE ENCUENTRA COMPROBADO | H25: =IF(AND(ABS(H34)<$B$34,ABS(H35)<$B$35,ABS(H36)<$B$36,ABS(H37)<$B$37,ABS(H38)<$B$38,ABS(H39)<$B$39,ABS(H40)<$B$40,ABS(H41)<$B$41),"EQUIPO SE ENCUENTRA COMPROBADO","EQUIPO TIENE ALGUNA AFECTACIÓN, ENVIAR A REVISIÓN") -> #VALUE! | J25: =B34 -> 1 | K25: =-B34 -> -1
B26: 124 | C26: 123.85 | D26: 123.99 | J26: =B35 -> 1.86 | K26: =-B35 -> -1.86
B27: 248 | C27: 247.93 | D27: 247.93 | J27: =B36 -> 3.72 | K27: =-B36 -> -3.72
B28: 372 | C28: 371.75 | D28: 371.9 | J28: =B37 -> 6 | K28: =-B37 -> -6
B29: 496 | C29: 495.59 | D29: 495.74 | J29: =B38 -> 6 | K29: =-B38 -> -6
B30: 620 | C30: 619.8 | D30: 619.8 | J30: =B39 -> 6 | K30: =-B39 -> -6
B31: 744 | C31: 743.91 | D31: 743.91 | J31: =B40 -> 6 | K31: =-B40 -> -6
B32: 870 | C32: 869.75 | D32: 869.9 | J32: =B41 -> 6 | K32: =-B41 -> -6
B33: Error Máximo permitido (psi) | C33: ERROR O | D33: ERROR 1 | E33: ERROR 2 | G33: DIFERENCIA ERROR 0-1 | H33: DIFERENCIA ERROR 0-2
B34: =IF(AND(B25>=15,B25<=70),1,IF(AND(B25>70,B25<=300),B25*0.015,IF(AND(B25>300,B25<=1000),6,IF(AND(B25>1000),B25*0.005,1)))) -> 1 | C34: =IF(C25="","",C25-B25) -> 0.01 | D34: =IF(D25="","",D25-B25) -> 0 | E34: =IF(E25="","",E25-B25) | G34: =C34-D34 -> 0.01 | H34: =C34-E34 -> #VALUE!
B35: =IF(AND(B26>=15,B26<=70),1,IF(AND(B26>70,B26<=300),B26*0.015,IF(AND(B26>300,B26<=1000),6,IF(AND(B26>1000),B26*0.005,1)))) -> 1.86 | C35: =IF(C26="","",C26-B26) -> -0.15 | D35: =IF(D26="","",D26-B26) -> -0.01 | E35: =IF(E26="","",E26-B26) | G35: =C35-D35 -> -0.14 | H35: =C35-E35 -> #VALUE!
B36: =IF(AND(B27>=15,B27<=70),1,IF(AND(B27>70,B27<=300),B27*0.015,IF(AND(B27>300,B27<=1000),6,IF(AND(B27>1000),B27*0.005,1)))) -> 3.72 | C36: =IF(C27="","",C27-B27) -> -0.07 | D36: =IF(D27="","",D27-B27) -> -0.07 | E36: =IF(E27="","",E27-B27) | G36: =C36-D36 -> 0 | H36: =C36-E36 -> #VALUE!
B37: =IF(AND(B28>=15,B28<=70),1,IF(AND(B28>70,B28<=300),B28*0.015,IF(AND(B28>300,B28<=1000),6,IF(AND(B28>1000),B28*0.005,1)))) -> 6 | C37: =IF(C28="","",C28-B28) -> -0.25 | D37: =IF(D28="","",D28-B28) -> -0.1 | E37: =IF(E28="","",E28-B28) | G37: =C37-D37 -> -0.15 | H37: =C37-E37 -> #VALUE!
B38: =IF(AND(B29>=15,B29<=70),1,IF(AND(B29>70,B29<=300),B29*0.015,IF(AND(B29>300,B29<=1000),6,IF(AND(B29>1000),B29*0.005,1)))) -> 6 | C38: =IF(C29="","",C29-B29) -> -0.41 | D38: =IF(D29="","",D29-B29) -> -0.26 | E38: =IF(E29="","",E29-B29) | G38: =C38-D38 -> -0.15 | H38: =C38-E38 -> #VALUE!
B39: =IF(AND(B30>=15,B30<=70),1,IF(AND(B30>70,B30<=300),B30*0.015,IF(AND(B30>300,B30<=1000),6,IF(AND(B30>1000),B30*0.005,1)))) -> 6 | C39: =IF(C30="","",C30-B30) -> -0.2 | D39: =IF(D30="","",D30-B30) -> -0.2 | E39: =IF(E30="","",E30-B30) | G39: =C39-D39 -> 0 | H39: =C39-E39 -> #VALUE!
B40: =IF(AND(B31>=15,B31<=70),1,IF(AND(B31>70,B31<=300),B31*0.015,IF(AND(B31>300,B31<=1000),6,IF(AND(B31>1000),B31*0.005,1)))) -> 6 | C40: =IF(C31="","",C31-B31) -> -0.09 | D40: =IF(D31="","",D31-B31) -> -0.09 | E40: =IF(E31="","",E31-B31) | G40: =C40-D40 -> 0 | H40: =C40-E40 -> #VALUE!
B41: =IF(AND(B32>=15,B32<=70),1,IF(AND(B32>70,B32<=300),B32*0.015,IF(AND(B32>300,B32<=1000),6,IF(AND(B32>1000),B32*0.005,1)))) -> 6 | C41: =IF(C32="","",C32-B32) -> -0.25 | D41: =IF(D32="","",D32-B32) -> -0.1 | E41: =IF(E32="","",E32-B32) | G41: =C41-D41 -> -0.15 | H41: =C41-E41 -> #VALUE!
B43: Validación de software
B44: Registro inicial
B45: X | C45: Corrección | D45: Corrección curva | E45: Valor VST | F45: Valor curva
...

Sheet VERIFICACIÓN DANFOSS 3625
B2: INTRUMENTO | C2: MARCA | D2: MODELO | E2: SERIAL | F2: FECHA DE CALIBRACIÓN | G2: FECHA PROGRAMADA PARA REGISTRO INICIAL | H2: FECHA PROGRAMADA COMPROBACIÓN 1 | I2: FECHA PROGRAMADA COMPROBACIÓN 2
B3: PATRÓN | C3: CRYSTAL | D3: =IF($C$3='CONTROL CALIBRACIONES'!$C$14,'CONTROL CALIBRACIONES'!E14,IF($C$3='CONTROL CALIBRACIONES'!$C$15,'CONTROL CALIBRACIONES'!E15,'CONTROL CALIBRACIONES'!E16)) -> XP2i | E3: =IF($C$3='CONTROL CALIBRACIONES'!$C$14,'CONTROL CALIBRACIONES'!F14,IF($C$3='CONTROL CALIBRACIONES'!$C$15,'CONTROL CALIBRACIONES'!F15,'CONTROL CALIBRACIONES'!F16)) -> 357309 | F3: ='CONTROL CALIBRACIONES'!G14 -> 45681 | G3: =F4+5 -> 45902 | H3: =IF(TODAY()-$F$3<=340,$F$4+120,"ERROR, CALIBRE EL PATRÓN") -> 46017 | I3: =IF(TODAY()-$F$3<=340,$F$4+240,"ERROR, CALIBRE EL PATRÓN") -> 46137
B4: INDICE BAJO VERIFICACIÓN (IBV) | C4: DANFOSS | D4: MBS3000 | E4: 20275210 | F4: ='CONTROL CALIBRACIONES'!G33 -> 45897
B6: DATOS Y RESULTADOS DE LA CALIBRACIÓN
B8: VALOR PATRÓN (psi) | C8: VALOR IBV (psi) | D8: ERROR (PSI) | E8: INCERTIDUMBRE | F8: Error permitido (+- psi) | G8: COMENTARIOS | H8: TEMPERATURA (°C) | I8: 20.9 | K8: Superior | L8: Inferior
A9: 1 | B9: 0 | C9: 0 | D9: =B9-C9 -> 0 | E9: 0.0083 | F9: 0.1 | G9: =IF(AND(ABS(D9)<F9,ABS(D10)<F10,ABS(D11)<F11,ABS(D12)<F12,ABS(D13)<F13,ABS(D14)<F14,ABS(D15)<F15,ABS(D16)<F16,ABS(D17)<F17,ABS(D18)<F18,ABS(D19)<F19,ABS(D20)<F20),"EQUIPO CUMPLE ESPECIFICACIÓN","EQUIPO NO CUMPLE ESPECIFICACIÓN") -> EQUIPO CUMPLE ESPECIFICACIÓN | H9: PRESIÓN ATMOSFERICA (hPa) | I9: 747.8 | K9: =F9 -> 0.1 | L9: =-F9 -> -0.1
A10: 2 | B10: 329 | C10: 324.36 | D10: =B10-C10 -> 4.64 | E10: 0.32 | F10: =IF(AND(B10>=15,B10<=70),2,IF(AND(B10>70,B10<=300),B10*0.03,IF(AND(B10>300,B10<=1000),12,IF(AND(B10>1000),B10*0.01,"Revisar")))) -> 12 | H10: HUMEDAD RELATIVA (%) | I10: 0.689 | K10: =F10 -> 12 | L10: =-F10 -> -12
A11: 3 | B11: 568 | C11: 560.51 | D11: =B11-C11 -> 7.49 | E11: 0.26 | F11: =IF(AND(B11>=15,B11<=70),2,IF(AND(B11>70,B11<=300),B11*0.03,IF(AND(B11>300,B11<=1000),12,IF(AND(B11>1000),B11*0.01,"Revisar")))) -> 12 | H11: ENTE CERTIFICADOR | I11: Flexilatina | K11: =F11 -> 12 | L11: =-F11 -> -12
A12: 4 | B12: 987 | C12: 976.94 | D12: =B12-C12 -> 10.06 | E12: 0.25 | F12: =IF(AND(B12>=15,B12<=70),2,IF(AND(B12>70,B12<=300),B12*0.03,IF(AND(B12>300,B12<=1000),12,IF(AND(B12>1000),B12*0.01,"Revisar")))) -> 12 | H12: FECHA DE CALIBRACIÓN | I12: =F4 -> 45897 | K12: =F12 -> 12 | L12: =-F12 -> -12
A13: 5 | B13: 1316 | C13: 1304.56 | D13: =B13-C13 -> 11.44 | E13: 0.11 | F13: =IF(AND(B13>=15,B13<=70),2,IF(AND(B13>70,B13<=300),B13*0.03,IF(AND(B13>300,B13<=1000),12,IF(AND(B13>1000),B13*0.01,"Revisar")))) -> 13.16 | H13: Después de que el equipo llega, se confirma que calibrando con un tiempo calendario de 1 año, el equipo sigue cumpliendo con las especificaiones requeridas, por lo cual se mantiene el periodo de un año según lo establecido en la OIML 10 método 1 | K13: =F13 -> 13.16 | L13: =-F13 -> -13.16
A14: 6 | B14: 1645 | C14: 1632.52 | D14: =B14-C14 -> 12.48 | E14: 0.18 | F14: =IF(AND(B14>=15,B14<=70),2,IF(AND(B14>70,B14<=300),B14*0.03,IF(AND(B14>300,B14<=1000),12,IF(AND(B14>1000),B14*0.01,"Revisar")))) -> 16.45 | K14: =F14 -> 16.45 | L14: =-F14 -> -16.45
A15: 7 | B15: 1974 | C15: 1961.72 | D15: =B15-C15 -> 12.28 | E15: 0.34 | F15: =IF(AND(B15>=15,B15<=70),2,IF(AND(B15>70,B15<=300),B15*0.03,IF(AND(B15>300,B15<=1000),12,IF(AND(B15>1000),B15*0.01,"Revisar")))) -> 19.74 | K15: =F15 -> 19.74 | L15: =-F15 -> -19.74
A16: 8 | B16: 2303 | C16: 2290.96 | D16: =B16-C16 -> 12.04 | E16: 0.24 | F16: =IF(AND(B16>=15,B16<=70),2,IF(AND(B16>70,B16<=300),B16*0.03,IF(AND(B16>300,B16<=1000),12,IF(AND(B16>1000),B16*0.01,"Revisar")))) -> 23.03 | K16: =F16 -> 23.03 | L16: =-F16 -> -23.03
A17: 9 | B17: 2632 | C17: 2620.43 | D17: =B17-C17 -> 11.57 | E17: 0.81 | F17: =IF(AND(B17>=15,B17<=70),2,IF(AND(B17>70,B17<=300),B17*0.03,IF(AND(B17>300,B17<=1000),12,IF(AND(B17>1000),B17*0.01,"Revisar")))) -> 26.32 | K17: =F17 -> 26.32 | L17: =-F17 -> -26.32
A18: 10 | B18: 2961 | C18: 2947.29 | D18: =B18-C18 -> 13.71 | E18: 0.26 | F18: =IF(AND(B18>=15,B18<=70),2,IF(AND(B18>70,B18<=300),B18*0.03,IF(AND(B18>300,B18<=1000),12,IF(AND(B18>1000),B18*0.01,"Revisar")))) -> 29.61 | K18: =F18 -> 29.61 | L18: =-F18 -> -29.61
A19: 11 | B19: 3290 | C19: 3276.58 | D19: =B19-C19 -> 13.42 | E19: 0.26 | F19: =IF(AND(B19>=15,B19<=70),2,IF(AND(B19>70,B19<=300),B19*0.03,IF(AND(B19>300,B19<=1000),12,IF(AND(B19>1000),B19*0.01,"Revisar")))) -> 32.9 | K19: =F19 -> 32.9 | L19: =-F19 -> -32.9
A20: 12 | B20: 3625 | C20: 3612.19 | D20: =B20-C20 -> 12.81 | E20: 0.51 | F20: =IF(AND(B20>=15,B20<=70),2,IF(AND(B20>70,B20<=300),B20*0.03,IF(AND(B20>300,B20<=1000),12,IF(AND(B20>1000),B20*0.01,"Revisar")))) -> 36.25 | K20: =F20 -> 36.25 | L20: =-F20 -> -36.25
B22: DATOS Y RESULTADOS DE LAS COMPROBACIONES
B23: Fecha | C23: 45911 | D23: 45924
B24: Responsable | C24: Wilder Alberto Suarez | D24: Andrés Felipe Ovalle
B25: VALOR PATRÓN (psi) | C25: VALOR REGISTRO INICIAL (psi) | D25: VALOR COMPROBACIÓN 1 (psi) | E25: VALOR COMPROBACIÓN 2 (psi) | G25: COMENTARIO COMPROBACIÓN 1 | H25: COMENTARIO COMPROBACIÓN 2 | J25: Superior | K25: Inferior
B26: 0 | C26: -0.03 | D26: -0.03 | G26: =IF(AND(ABS(G35)<$B$35,ABS(G36)<$B$36,ABS(G37)<$B$37,ABS(G38)<$B$38,ABS(G39)<$B$39,ABS(G40)<$B$40,ABS(G41)<$B$41,ABS(G42)<$B$42),"EQUIPO SE ENCUENTRA COMPROBADO","EQUIPO TIENE ALGUNA AFECTACIÓN, ENVIAR A REVISIÓN") -> EQUIPO SE ENCUENTRA COMPROBADO | H26: =IF(AND(ABS(H35)<$B$35,ABS(H36)<$B$36,ABS(H37)<$B$37,ABS(H38)<$B$38,ABS(H39)<$B$39,ABS(H40)<$B$40,ABS(H41)<$B$41,ABS(H42)<$B$42),"EQUIPO SE ENCUENTRA COMPROBADO","EQUIPO TIENE ALGUNA AFECTACIÓN, ENVIAR A REVISIÓN") -> #VALUE! | J26: =B35 -> 1 | K26: =-B35 -> -1
B27: 428 | C27: 428.79 | D27: 428.18 | J27: =B36 -> 6 | K27: =-B36 -> -6
B28: 856 | C28: 856.46 | D28: 856.43 | J28: =B37 -> 6 | K28: =-B37 -> -6
B29: 1284 | C29: 1283.88 | D29: 1283.88 | J29: =B38 -> 6.42 | K29: =-B38 -> -6.42
B30: 1712 | C30: 1711.76 | D30: 1711.16 | J30: =B39 -> 8.56 | K30: =-B39 -> -8.56
B31: 2140 | C31: 2138.76 | D31: 2138.76 | J31: =B40 -> 10.7 | K31: =-B40 -> -10.7
B32: 2568 | C32: 2565.9 | D32: 2565.9 | J32: =B41 -> 12.84 | K32: =-B41 -> -12.84
B33: 3000 | C33: 2998.22 | D33: 2998.22 | J33: =B42 -> 15 | K33: =-B42 -> -15
B34: Error Máximo permitido (psi) | C34: ERROR O | D34: ERROR 1 | E34: ERROR 2 | G34: DIFERENCIA ERROR 0-1 | H34: DIFERENCIA ERROR 0-2
B35: =IF(AND(B26>=15,B26<=70),1,IF(AND(B26>70,B26<=300),B26*0.015,IF(AND(B26>300,B26<=1000),6,IF(AND(B26>1000),B26*0.005,1)))) -> 1 | C35: =IF(C26="","",C26-B26) -> -0.03 | D35: =IF(D26="","",D26-B26) -> -0.03 | E35: =IF(E26="","",E26-B26) | G35: =C35-D35 -> 0 | H35: =C35-E35 -> #VALUE!
B36: =IF(AND(B27>=15,B27<=70),1,IF(AND(B27>70,B27<=300),B27*0.015,IF(AND(B27>300,B27<=1000),6,IF(AND(B27>1000),B27*0.005,1)))) -> 6 | C36: =IF(C27="","",C27-B27) -> 0.79 | D36: =IF(D27="","",D27-B27) -> 0.18 | E36: =IF(E27="","",E27-B27) | G36: =C36-D36 -> 0.61 | H36: =C36-E36 -> #VALUE!
B37: =IF(AND(B28>=15,B28<=70),1,IF(AND(B28>70,B28<=300),B28*0.015,IF(AND(B28>300,B28<=1000),6,IF(AND(B28>1000),B28*0.005,1)))) -> 6 | C37: =IF(C28="","",C28-B28) -> 0.46 | D37: =IF(D28="","",D28-B28) -> 0.43 | E37: =IF(E28="","",E28-B28) | G37: =C37-D37 -> 0.03 | H37: =C37-E37 -> #VALUE!
B38: =IF(AND(B29>=15,B29<=70),1,IF(AND(B29>70,B29<=300),B29*0.015,IF(AND(B29>300,B29<=1000),6,IF(AND(B29>1000),B29*0.005,1)))) -> 6.42 | C38: =IF(C29="","",C29-B29) -> -0.12 | D38: =IF(D29="","",D29-B29) -> -0.12 | E38: =IF(E29="","",E29-B29) | G38: =C38-D38 -> 0 | H38: =C38-E38 -> #VALUE!
B39: =IF(AND(B30>=15,B30<=70),1,IF(AND(B30>70,B30<=300),B30*0.015,IF(AND(B30>300,B30<=1000),6,IF(AND(B30>1000),B30*0.005,1)))) -> 8.56 | C39: =IF(C30="","",C30-B30) -> -0.24 | D39: =IF(D30="","",D30-B30) -> -0.84 | E39: =IF(E30="","",E30-B30) | G39: =C39-D39 -> 0.6 | H39: =C39-E39 -> #VALUE!
B40: =IF(AND(B31>=15,B31<=70),1,IF(AND(B31>70,B31<=300),B31*0.015,IF(AND(B31>300,B31<=1000),6,IF(AND(B31>1000),B31*0.005,1)))) -> 10.7 | C40: =IF(C31="","",C31-B31) -> -1.24 | D40: =IF(D31="","",D31-B31) -> -1.24 | E40: =IF(E31="","",E31-B31) | G40: =C40-D40 -> 0 | H40: =C40-E40 -> #VALUE!
B41: =IF(AND(B32>=15,B32<=70),1,IF(AND(B32>70,B32<=300),B32*0.015,IF(AND(B32>300,B32<=1000),6,IF(AND(B32>1000),B32*0.005,1)))) -> 12.84 | C41: =IF(C32="","",C32-B32) -> -2.1 | D41: =IF(D32="","",D32-B32) -> -2.1 | E41: =IF(E32="","",E32-B32) | G41: =C41-D41 -> 0 | H41: =C41-E41 -> #VALUE!
B42: =IF(AND(B33>=15,B33<=70),1,IF(AND(B33>70,B33<=300),B33*0.015,IF(AND(B33>300,B33<=1000),6,IF(AND(B33>1000),B33*0.005,1)))) -> 15 | C42: =IF(C33="","",C33-B33) -> -1.78 | D42: =IF(D33="","",D33-B33) -> -1.78 | E42: =IF(E33="","",E33-B33) | G42: =C42-D42 -> 0 | H42: =C42-E42 -> #VALUE!
B44: Validación de software
B45: Registro inicial
...

Sheet VERIFICACIÓN DANFOSS 145 
B2: INTRUMENTO | C2: MARCA | D2: MODELO | E2: SERIAL | F2: FECHA DE CALIBRACIÓN | G2: FECHA PROGRAMADA PARA REGISTRO INICIAL | H2: FECHA PROGRAMADA COMPROBACIÓN 1 | I2: FECHA PROGRAMADA COMPROBACIÓN 2
